Workbook

Sheet Dataset
A1: Company | B1: Sector | C1: Financial Year | D1: Indicator | E1: Category | F1: Value | G1: Unit | H1: Source Document | I1: Page Reference | J1: Notes | K1: Lookup Key (auto)
A2: AECI | B2: Chemicals | C2: FY2025 | D2: Revenue | E2: Financial | F2: 32183 | G2: Rm | H2: AECI 2025 Integrated Report | I2: 9 | J2: Continuing operations | K2: =A2&"|"&D2&"|"&C2 -> AECI|Revenue|FY2025
A3: AECI | B3: Chemicals | C3: FY2024 | D3: Revenue | E3: Financial | F3: 33598 | G3: Rm | H3: AECI 2025 Integrated Report | I3: 9 | J3: Restated comparative shown in FY2025 report | K3: =A3&"|"&D3&"|"&C3 -> AECI|Revenue|FY2024
A4: AECI | B4: Chemicals | C4: FY2025 | D4: EBITDA | E4: Financial | F4: 3412 | G4: Rm | H4: AECI 2025 Integrated Report | I4: 9 | K4: =A4&"|"&D4&"|"&C4 -> AECI|EBITDA|FY2025
A5: AECI | B5: Chemicals | C5: FY2024 | D5: EBITDA | E5: Financial | F5: 3034 | G5: Rm | H5: AECI 2025 Integrated Report | I5: 9 | K5: =A5&"|"&D5&"|"&C5 -> AECI|EBITDA|FY2024
A6: AECI | B6: Chemicals | C6: FY2025 | D6: EBITDA margin | E6: Financial | F6: 11 | G6: % | H6: AECI 2025 Integrated Report | I6: 9 | K6: =A6&"|"&D6&"|"&C6 -> AECI|EBITDA margin|FY2025
A7: AECI | B7: Chemicals | C7: FY2024 | D7: EBITDA margin | E7: Financial | F7: 9 | G7: % | H7: AECI 2025 Integrated Report | I7: 9 | K7: =A7&"|"&D7&"|"&C7 -> AECI|EBITDA margin|FY2024
A8: AECI | B8: Chemicals | C8: FY2025 | D8: HEPS | E8: Financial | F8: 1068 | G8: cents | H8: AECI 2025 Integrated Report | I8: 9 | K8: =A8&"|"&D8&"|"&C8 -> AECI|HEPS|FY2025
A9: AECI | B9: Chemicals | C9: FY2024 | D9: HEPS | E9: Financial | F9: 716 | G9: cents | H9: AECI 2025 Integrated Report | I9: 9 | K9: =A9&"|"&D9&"|"&C9 -> AECI|HEPS|FY2024
A10: AECI | B10: Chemicals | C10: FY2025 | D10: Net debt | E10: Financial | F10: 0.5 | G10: R billion | H10: AECI 2025 Integrated Report | I10: 9 | K10: =A10&"|"&D10&"|"&C10 -> AECI|Net debt|FY2025
A11: AECI | B11: Chemicals | C11: FY2024 | D11: Net debt | E11: Financial | F11: 3.7 | G11: R billion | H11: AECI 2025 Integrated Report | I11: 9 | K11: =A11&"|"&D11&"|"&C11 -> AECI|Net debt|FY2024
A12: AECI | B12: Chemicals | C12: FY2025 | D12: ROIC | E12: Financial | F12: 13 | G12: % | H12: AECI 2025 Integrated Report | I12: 9 | K12: =A12&"|"&D12&"|"&C12 -> AECI|ROIC|FY2025
A13: AECI | B13: Chemicals | C13: FY2024 | D13: ROIC | E13: Financial | F13: 9 | G13: % | H13: AECI 2025 Integrated Report | I13: 9 | K13: =A13&"|"&D13&"|"&C13 -> AECI|ROIC|FY2024
A14: AECI | B14: Chemicals | C14: FY2025 | D14: Total dividend | E14: Financial | F14: 228 | G14: cents per share | H14: AECI 2025 Integrated Report | I14: 9 | K14: =A14&"|"&D14&"|"&C14 -> AECI|Total dividend|FY2025
A15: AECI | B15: Chemicals | C15: FY2024 | D15: Total dividend | E15: Financial | F15: 219 | G15: cents per share | H15: AECI 2025 Integrated Report | I15: 9 | K15: =A15&"|"&D15&"|"&C15 -> AECI|Total dividend|FY2024
A16: AECI | B16: Chemicals | C16: FY2022 | D16: EBITDA (core) | E16: Financial | F16: 3100 | G16: Rm | H16: AECI 2025 Integrated Report | I16: 13 | J16: Baseline year in strategy KPI table | K16: =A16&"|"&D16&"|"&C16 -> AECI|EBITDA (core)|FY2022
A17: AECI | B17: Chemicals | C17: FY2023 | D17: EBITDA (core) | E17: Financial | F17: 3401 | G17: Rm | H17: AECI 2025 Integrated Report | I17: 13 | K17: =A17&"|"&D17&"|"&C17 -> AECI|EBITDA (core)|FY2023
A18: AECI | B18: Chemicals | C18: FY2024 | D18: EBITDA (core) | E18: Financial | F18: 2957 | G18: Rm | H18: AECI 2025 Integrated Report | I18: 13 | K18: =A18&"|"&D18&"|"&C18 -> AECI|EBITDA (core)|FY2024
A19: AECI | B19: Chemicals | C19: FY2025 | D19: EBITDA (core) | E19: Financial | F19: 3248 | G19: Rm | H19: AECI 2025 Integrated Report | I19: 13 | K19: =A19&"|"&D19&"|"&C19 -> AECI|EBITDA (core)|FY2025
A20: AECI | B20: Chemicals | C20: FY2022 | D20: ROIC (strategy KPI) | E20: Financial | F20: 12 | G20: % | H20: AECI 2025 Integrated Report | I20: 13 | K20: =A20&"|"&D20&"|"&C20 -> AECI|ROIC (strategy KPI)|FY2022
A21: AECI | B21: Chemicals | C21: FY2023 | D21: ROIC (strategy KPI) | E21: Financial | F21: 14 | G21: % | H21: AECI 2025 Integrated Report | I21: 13 | K21: =A21&"|"&D21&"|"&C21 -> AECI|ROIC (strategy KPI)|FY2023
A22: AECI | B22: Chemicals | C22: FY2024 | D22: ROIC (strategy KPI) | E22: Financial | F22: 15 | G22: % | H22: AECI 2025 Integrated Report | I22: 13 | K22: =A22&"|"&D22&"|"&C22 -> AECI|ROIC (strategy KPI)|FY2024
A23: AECI | B23: Chemicals | C23: FY2025 | D23: ROIC (strategy KPI) | E23: Financial | F23: 16 | G23: % | H23: AECI 2025 Integrated Report | I23: 13 | K23: =A23&"|"&D23&"|"&C23 -> AECI|ROIC (strategy KPI)|FY2025
A24: AECI | B24: Chemicals | C24: FY2022 | D24: Net debt/EBITDA | E24: Financial | F24: -1.5 | G24: x | H24: AECI 2025 Integrated Report | I24: 13 | K24: =A24&"|"&D24&"|"&C24 -> AECI|Net debt/EBITDA|FY2022
A25: AECI | B25: Chemicals | C25: FY2023 | D25: Net debt/EBITDA | E25: Financial | F25: 1.2 | G25: x | H25: AECI 2025 Integrated Report | I25: 13 | K25: =A25&"|"&D25&"|"&C25 -> AECI|Net debt/EBITDA|FY2023
A26: AECI | B26: Chemicals | C26: FY2024 | D26: Net debt/EBITDA | E26: Financial | F26: 1.2 | G26: x | H26: AECI 2025 Integrated Report | I26: 13 | K26: =A26&"|"&D26&"|"&C26 -> AECI|Net debt/EBITDA|FY2024
A27: AECI | B27: Chemicals | C27: FY2025 | D27: Net debt/EBITDA | E27: Financial | F27: 0.1 | G27: x | H27: AECI 2025 Integrated Report | I27: 13 | K27: =A27&"|"&D27&"|"&C27 -> AECI|Net debt/EBITDA|FY2025
A28: AECI | B28: Chemicals | C28: FY2025 | D28: TRIR (Total Recordable Injury Rate) | E28: Social | F28: 0.2 | G28: rate | H28: AECI 2025 Integrated Report | I28: 9 | K28: =A28&"|"&D28&"|"&C28 -> AECI|TRIR (Total Recordable Injury Rate)|FY2025
... A37: AECI | B37: Chemicals | C37: FY2024 | D37: Scope 3 GHG emissions | E37: Environmental | F37: 1081153 | G37: tCO2e | H37: AECI 2025 Integrated Report | I37: 9 | K37: =A37&"|"&D37&"|"&C37 -> AECI|Scope 3 GHG emissions|FY2024
A38: AECI | B38: Chemicals | C38: FY2025 | D38: Total carbon footprint (Scope 1+2) | E38: Environmental | F38: =F32+F34 -> 365500 | G38: tCO2e | H38: AECI 2025 Integrated Report | I38: 9 | J38: [Formula: Scope 1 + Scope 2, linked to rows above] | K38: =A38&"|"&D38&"|"&C38 -> AECI|Total carbon footprint (Scope 1+2)|FY2025
A39: AECI | B39: Chemicals | C39: FY2024 | D39: Total carbon footprint (Scope 1+2) | E39: Environmental | F39: =F33+F35 -> 416337 | G39: tCO2e | H39: AECI 2025 Integrated Report | I39: 9 | J39: [Formula: Scope 1 + Scope 2, linked to rows above] | K39: =A39&"|"&D39&"|"&C39 -> AECI|Total carbon footprint (Scope 1+2)|FY2024
A40: AECI | B40: Chemicals | C40: FY2025 | D40: Hazardous waste disposed | E40: Environmental | F40: 9943 | G40: tonnes | H40: AECI 2025 Integrated Report | I40: 9 | K40: =A40&"|"&D40&"|"&C40 -> AECI|Hazardous waste disposed|FY2025
A41: AECI | B41: Chemicals | C41: FY2024 | D41: Hazardous waste disposed | E41: Environmental | F41: 12722 | G41: tonnes | H41: AECI 2025 Integrated Report | I41: 9 | K41: =A41&"|"&D41&"|"&C41 -> AECI|Hazardous waste disposed|FY2024
A42: AECI | B42: Chemicals | C42: FY2025 | D42: Renewable electricity | E42: Environmental | F42: 16669 | G42: MWh | H42: AECI 2025 Integrated Report | I42: 9 | K42: =A42&"|"&D42&"|"&C42 -> AECI|Renewable electricity|FY2025
A43: AECI | B43: Chemicals | C43: FY2024 | D43: Renewable electricity | E43: Environmental | F43: 8663 | G43: MWh | H43: AECI 2025 Integrated Report | I43: 9 | K43: =A43&"|"&D43&"|"&C43 -> AECI|Renewable electricity|FY2024
A44: AECI | B44: Chemicals | C44: FY2025 | D44: Female representation, top/senior/middle mgmt | E44: Social | F44: 30 | G44: % | H44: AECI 2025 Integrated Report | I44: 9 | K44: =A44&"|"&D44&"|"&C44 -> AECI|Female representation, top/senior/middle mgmt|FY2025
A45: AECI | B45: Chemicals | C45: FY2024 | D45: Female representation, top/senior/middle mgmt | E45: Social | F45: 29 | G45: % | H45: AECI 2025 Integrated Report | I45: 9 | K45: =A45&"|"&D45&"|"&C45 -> AECI|Female representation, top/senior/middle mgmt|FY2024
A46: AECI | B46: Chemicals | C46: FY2025 | D46: Total employees | E46: Social | F46: 5459 | G46: number | H46: AECI 2025 Integrated Report | I46: 11 | J46: Across >20 countries | K46: =A46&"|"&D46&"|"&C46 -> AECI|Total employees|FY2025
A47: AECI | B47: Chemicals | C47: FY2025 | D47: Social responsibility spend | E47: Social | F47: 33 | G47: Rm | H47: AECI 2025 Integrated Report | I47: 9 | K47: =A47&"|"&D47&"|"&C47 -> AECI|Social responsibility spend|FY2025
A48: AECI | B48: Chemicals | C48: FY2024 | D48: Social responsibility spend | E48: Social | F48: 28.5 | G48: Rm | H48: AECI 2025 Integrated Report | I48: 9 | K48: =A48&"|"&D48&"|"&C48 -> AECI|Social responsibility spend|FY2024
...

Sheet Data Dictionary
A1: Variable | B1: Definition | C1: Measurement / Unit | D1: Capital (IIRC Six Capitals) | E1: Category | F1: Data Type | G1: Source Type
A2: Revenue | B2: Total revenue/turnover/sales reported in the consolidated income statement | C2: Rm / US$m | D2: Financial | E2: Financial performance | F2: Continuous (numeric) | G2: Integrated report, audited financial statements section
A3: EBITDA / Adjusted EBITDA | B3: Earnings before interest, tax, depreciation and amortisation, as defined by each company | C3: Rm / US$m | D3: Financial | E3: Financial performance | F3: Continuous (numeric) | G3: Integrated report, financial highlights / CFO report
A4: HEPS (Headline Earnings Per Share) | B4: Headline earnings attributable to ordinary shareholders divided by the weighted average number of shares in issue, per JSE/SAICA Circular definition | C4: cents / US cents | D4: Financial | E4: Financial performance | F4: Continuous (numeric) | G4: Integrated report, financial highlights
A5: Net debt / Net debt position | B5: Total interest-bearing borrowings less cash and cash equivalents | C5: Rm / R billion | D5: Financial | E5: Financial performance | F5: Continuous (numeric) | G5: Integrated report, financial highlights
A6: ROIC / ROCE | B6: Return on Invested Capital / Return on Capital Employed, company-specific formula, generally NOPAT (or operating profit) divided by average invested capital | C6: % | D6: Financial | E6: Financial performance | F6: Continuous (numeric) | G6: Integrated report, strategy/KPI table
A7: Scope 1 GHG emissions | B7: Direct greenhouse gas emissions from owned or controlled sources, reported per the GHG Protocol | C7: tCO2e | D7: Natural | E7: Environmental / climate | F7: Continuous (numeric) | G7: Integrated / sustainability report, ESG data table
A8: Scope 2 GHG emissions | B8: Indirect GHG emissions from the generation of purchased electricity, steam, heat or cooling consumed | C8: tCO2e | D8: Natural | E8: Environmental / climate | F8: Continuous (numeric) | G8: Integrated / sustainability report, ESG data table
A9: Scope 3 GHG emissions | B9: Other indirect GHG emissions occurring in a company's value chain | C9: tCO2e | D9: Natural | E9: Environmental / climate | F9: Continuous (numeric) | G9: Integrated / sustainability report, ESG data table (where disclosed)
A10: GHG emission reduction vs baseline | B10: Percentage reduction in emissions achieved against a stated historical baseline year, as reported by the company toward its stated target | C10: % reduction vs baseline year | D10: Natural | E10: Environmental / climate | F10: Continuous (numeric) | G10: Integrated report, climate change section
A11: Renewable energy use | B11: Electricity/energy sourced from renewable generation (solar PV, wind, biomass, etc.) | C11: MWh | D11: Natural / Manufactured | E11: Environmental | F11: Continuous (numeric) | G11: Integrated report, environmental performance section
A12: Hazardous waste disposed | B12: Tonnes of hazardous waste sent for disposal (landfill, incineration, or licensed treatment) | C12: tonnes | D12: Natural | E12: Environmental | F12: Continuous (numeric) | G12: Integrated report, environmental performance section
... A21: Financial Year (FY) | B21: Company reporting year; note that fiscal year-ends differ (AECI, ArcelorMittal SA, Omnia and Sasol = 30 June or calendar; Sappi = year ended September) | C21: categorical (FY2021-FY2025) | D21: - | E21: Identifier | F21: Categorical | G21: -
A24: Exchange rates used for Sappi's USD-to-ZAR conversion
A26: Financial Year | B26: Average USD/ZAR rate | C26: Source
A27: FY2021 | B27: 14.7955 | C27: Nedbank Group Economic Unit, Annual Average Exchange Rates
A28: FY2022 | B28: 16.372 | C28: Nedbank Group Economic Unit, Annual Average Exchange Rates
A29: FY2023 | B29: 18.4519 | C29: Nedbank Group Economic Unit, Annual Average Exchange Rates
A30: FY2024 | B30: 18.3308 | C30: Nedbank Group Economic Unit, Annual Average Exchange Rates
A31: FY2025 | B31: 17.877 | C31: Nedbank Group Economic Unit, Annual Average Exchange Rates
A33: Note: Sappi's financial year ends 30 September; calendar-year average rates are used as a reasonable proxy for its fiscal year, disclosed here rather than treated as exact. Applying each year's own average rate (rather than a single constant rate) means the resulting % change in Rand terms reflects both Sappi's underlying US-dollar performance and the Rand's depreciation over the period (~21% from FY2021 to FY2025) — this is flagged explicitly wherever Sappi's Rand-converted trend is discussed in the written report.

Sheet ESG-Financial Risk Scorecard
A1: ESG-Adjusted Financial Risk Scorecard
A2: Digital/analytical artefact — Phase 5 (ESG-to-Financial-Risk Model). Value columns (C, D) are live formulas that look up the Dataset sheet by company, indicator and financial year (via Dataset!K, the auto-built lookup key), so correcting or extending the Dataset automatically updates this sheet. Blue cells = weight inputs (H), the only true judgement inputs in this model. Black cells = calculated. Yellow = data not yet available (see Notes) and defaulted to a neutral score of 3 rather than guessed.
A4: Company | B4: Indicator | C4: FY2021 value | D4: FY2025 value | E4: % change (FY21→FY25) | F4: Direction preferred | G4: Normalised score (1-5) 5=best | H4: Weight | I4: Weighted score | J4: Notes
A5: AECI | B5: Total carbon footprint (Scope 1+2, tCO2e) | C5: =IFERROR(INDEX(Dataset!$F$2:$F$1000,MATCH("AECI|Total carbon footprint (Scope 1+2)|FY2024",Dataset!$K$2:$K$1000,0)),"n/a") -> 416337 | D5: =IFERROR(INDEX(Dataset!$F$2:$F$1000,MATCH("AECI|Total carbon footprint (Scope 1+2)|FY2025",Dataset!$K$2:$K$1000,0)),"n/a") -> 365500 | E5: =IFERROR((D5-C5)/ABS(C5),"n/a") -> -0.12210541 | F5: down | G5: =IFERROR(MIN(5,MAX(1,3-(D5-C5)/ABS(C5)*5)),3) -> 3.610527 | H5: 0.2 | I5: =G5*H5 -> 0.72210541 | J5: FY2021 not disclosed in same basis; using FY2024=416,337 as prior-year comparator
A6: AECI | B6: TRIR (safety) | C6: =IFERROR(INDEX(Dataset!$F$2:$F$1000,MATCH("AECI|TRIR (Total Recordable Injury Rate)|FY2024",Dataset!$K$2:$K$1000,0)),"n/a") -> 0.31 | D6: =IFERROR(INDEX(Dataset!$F$2:$F$1000,MATCH("AECI|TRIR (Total Recordable Injury Rate)|FY2025",Dataset!$K$2:$K$1000,0)),"n/a") -> 0.2 | E6: =IFERROR((D6-C6)/ABS(C6),"n/a") -> -0.35483871 | F6: down | G6: =IFERROR(MIN(5,MAX(1,3-(D6-C6)/ABS(C6)*5)),3) -> 4.7741935 | H6: 0.15 | I6: =G6*H6 -> 0.71612903 | J6: FY2024 comparator = 0.31
A7: AECI | B7: EBITDA margin (%) | C7: =IFERROR(INDEX(Dataset!$F$2:$F$1000,MATCH("AECI|EBITDA margin|FY2024",Dataset!$K$2:$K$1000,0)),"n/a") -> 9 | D7: =IFERROR(INDEX(Dataset!$F$2:$F$1000,MATCH("AECI|EBITDA margin|FY2025",Dataset!$K$2:$K$1000,0)),"n/a") -> 11 | E7: =IFERROR((D7-C7)/ABS(C7),"n/a") -> 0.22222222 | F7: up | G7: =IFERROR(MIN(5,MAX(1,3+(D7-C7)/ABS(C7)*5)),3) -> 4.1111111 | H7: 0.2 | I7: =G7*H7 -> 0.82222222 | J7: FY2022 baseline used (FY2021 EBITDA margin not disclosed on comparable core basis)
A8: AECI | B8: ROIC (%) | C8: =IFERROR(INDEX(Dataset!$F$2:$F$1000,MATCH("AECI|ROIC|FY2024",Dataset!$K$2:$K$1000,0)),"n/a") -> 9 | D8: =IFERROR(INDEX(Dataset!$F$2:$F$1000,MATCH("AECI|ROIC|FY2025",Dataset!$K$2:$K$1000,0)),"n/a") -> 13 | E8: =IFERROR((D8-C8)/ABS(C8),"n/a") -> 0.44444444 | F8: up | G8: =IFERROR(MIN(5,MAX(1,3+(D8-C8)/ABS(C8)*5)),3) -> 5 | H8: 0.2 | I8: =G8*H8 -> 1 | J8: FY2022 baseline (strategy KPI table)
A9: AECI | B9: Female representation, management (%) | C9: =IFERROR(INDEX(Dataset!$F$2:$F$1000,MATCH("AECI|Female representation, top/senior/middle mgmt|FY2024",Dataset!$K$2:$K$1000,0)),"n/a") -> 29 | D9: =IFERROR(INDEX(Dataset!$F$2:$F$1000,MATCH("AECI|Female representation, top/senior/middle mgmt|FY2025",Dataset!$K$2:$K$1000,0)),"n/a") -> 30 | E9: =IFERROR((D9-C9)/ABS(C9),"n/a") -> 0.034482759 | F9: up | G9: =IFERROR(MIN(5,MAX(1,3+(D9-C9)/ABS(C9)*5)),3) -> 3.1724138 | H9: 0.15 | I9: =G9*H9 -> 0.47586207 | J9: FY2024 comparator = 29%
A10: AECI | B10: Net debt/EBITDA (x) | C10: =IFERROR(INDEX(Dataset!$F$2:$F$1000,MATCH("AECI|Net debt/EBITDA|FY2024",Dataset!$K$2:$K$1000,0)),"n/a") -> 1.2 | D10: =IFERROR(INDEX(Dataset!$F$2:$F$1000,MATCH("AECI|Net debt/EBITDA|FY2025",Dataset!$K$2:$K$1000,0)),"n/a") -> 0.1 | E10: =IFERROR((D10-C10)/ABS(C10),"n/a") -> -0.91666667 | F10: down | G10: =IFERROR(MIN(5,MAX(1,3-(D10-C10)/ABS(C10)*5)),3) -> 5 | H10: 0.1 | I10: =G10*H10 -> 0.5 | J10: FY2022 baseline
A11: AECI | B11: COMPOSITE ESG-ADJUSTED FINANCIAL RISK SCORE | I11: =SUM(I5:I10)/SUM(H5:H10) -> 4.2363187
A13: ArcelorMittal SA | B13: Fatalities | C13: =IFERROR(INDEX(Dataset!$F$2:$F$1000,MATCH("ArcelorMittal SA|Employee & contractor fatalities|FY2021",Dataset!$K$2:$K$1000,0)),"n/a") -> 6 | D13: =IFERROR(INDEX(Dataset!$F$2:$F$1000,MATCH("ArcelorMittal SA|Employee & contractor fatalities|FY2025",Dataset!$K$2:$K$1000,0)),"n/a") -> 1 | E13: =IFERROR((D13-C13)/ABS(C13),"n/a") -> -0.83333333 | F13: down | G13: =IFERROR(MIN(5,MAX(1,3-(D13-C13)/ABS(C13)*5)),3) -> 5 | H13: 0.2 | I13: =G13*H13 -> 1
A14: ArcelorMittal SA | B14: LTIFR | C14: =IFERROR(INDEX(Dataset!$F$2:$F$1000,MATCH("ArcelorMittal SA|LTIFR|FY2021",Dataset!$K$2:$K$1000,0)),"n/a") -> 0.98 | D14: =IFERROR(INDEX(Dataset!$F$2:$F$1000,MATCH("ArcelorMittal SA|LTIFR|FY2025",Dataset!$K$2:$K$1000,0)),"n/a") -> 0.62 | E14: =IFERROR((D14-C14)/ABS(C14),"n/a") -> -0.36734694 | F14: down | G14: =IFERROR(MIN(5,MAX(1,3-(D14-C14)/ABS(C14)*5)),3) -> 4.8367347 | H14: 0.15 | I14: =G14*H14 -> 0.7255102
A15: ArcelorMittal SA | B15: CO2 intensity (tCO2e/t liquid steel) | C15: =IFERROR(INDEX(Dataset!$F$2:$F$1000,MATCH("ArcelorMittal SA|CO2 emissions intensity|FY2021",Dataset!$K$2:$K$1000,0)),"n/a") -> 2.72 | D15: =IFERROR(INDEX(Dataset!$F$2:$F$1000,MATCH("ArcelorMittal SA|CO2 emissions intensity|FY2025",Dataset!$K$2:$K$1000,0)),"n/a") -> 3.26 | E15: =IFERROR((D15-C15)/ABS(C15),"n/a") -> 0.19852941 | F15: down | G15: =IFERROR(MIN(5,MAX(1,3-(D15-C15)/ABS(C15)*5)),3) -> 2.0073529 | H15: 0.2 | I15: =G15*H15 -> 0.40147059 | J15: Intensity worsened FY21-FY25
A16: ArcelorMittal SA | B16: Return on capital employed (%) | C16: =IFERROR(INDEX(Dataset!$F$2:$F$1000,MATCH("ArcelorMittal SA|Return on capital employed|FY2021",Dataset!$K$2:$K$1000,0)),"n/a") -> 53.9 | D16: =IFERROR(INDEX(Dataset!$F$2:$F$1000,MATCH("ArcelorMittal SA|Return on capital employed|FY2025",Dataset!$K$2:$K$1000,0)),"n/a") -> -16.07 | E16: =IFERROR((D16-C16)/ABS(C16),"n/a") -> -1.2981447 | F16: up | G16: =IFERROR(MIN(5,MAX(1,3+(D16-C16)/ABS(C16)*5)),3) -> 1 | H16: 0.25 | I16: =G16*H16 -> 0.25 | J16: Sharp deterioration
A17: ArcelorMittal SA | B17: B-BBEE compliance score | C17: =IFERROR(INDEX(Dataset!$F$2:$F$1000,MATCH("ArcelorMittal SA|B-BBEE compliance score|FY2021",Dataset!$K$2:$K$1000,0)),"n/a") -> 8 | D17: =IFERROR(INDEX(Dataset!$F$2:$F$1000,MATCH("ArcelorMittal SA|B-BBEE compliance score|FY2025",Dataset!$K$2:$K$1000,0)),"n/a") -> 4 | E17: =IFERROR((D17-C17)/ABS(C17),"n/a") -> -0.5 | F17: up | G17: =IFERROR(MIN(5,MAX(1,3+(D17-C17)/ABS(C17)*5)),3) -> 1 | H17: 0.1 | I17: =G17*H17 -> 0.1 | J17: Score declined (self-assessed FY2025)
A18: ArcelorMittal SA | B18: Net debt (Rm) | C18: =IFERROR(INDEX(Dataset!$F$2:$F$1000,MATCH("ArcelorMittal SA|Net debt position|FY2021",Dataset!$K$2:$K$1000,0)),"n/a") -> 1258 | D18: =IFERROR(INDEX(Dataset!$F$2:$F$1000,MATCH("ArcelorMittal SA|Net debt position|FY2025",Dataset!$K$2:$K$1000,0)),"n/a") -> 6763 | E18: =IFERROR((D18-C18)/ABS(C18),"n/a") -> 4.3759936 | F18: down | G18: =IFERROR(MIN(5,MAX(1,3-(D18-C18)/ABS(C18)*5)),3) -> 1 | H18: 0.1 | I18: =G18*H18 -> 0.1 | J18: Rising net debt
A19: ArcelorMittal SA | B19: COMPOSITE ESG-ADJUSTED FINANCIAL RISK SCORE | I19: =SUM(I13:I18)/SUM(H13:H18) -> 2.5769808
A21: Omnia | B21: Scope 1 GHG emissions (t) | C21: =IFERROR(INDEX(Dataset!$F$2:$F$1000,MATCH("Omnia|Scope 1 GHG emissions|FY2021",Dataset!$K$2:$K$1000,0)),"n/a") -> 178139 | D21: =IFERROR(INDEX(Dataset!$F$2:$F$1000,MATCH("Omnia|Scope 1 GHG emissions|FY2025",Dataset!$K$2:$K$1000,0)),"n/a") -> 70437 | E21: =IFERROR((D21-C21)/ABS(C21),"n/a") -> -0.60459529 | F21: down | G21: =IFERROR(MIN(5,MAX(1,3-(D21-C21)/ABS(C21)*5)),3) -> 5 | H21: 0.2 | I21: =G21*H21 -> 1
A22: Omnia | B22: Scope 2 GHG emissions (t) | C22: =IFERROR(INDEX(Dataset!$F$2:$F$1000,MATCH("Omnia|Scope 2 GHG emissions|FY2021",Dataset!$K$2:$K$1000,0)),"n/a") -> 83361 | D22: =IFERROR(INDEX(Dataset!$F$2:$F$1000,MATCH("Omnia|Scope 2 GHG emissions|FY2025",Dataset!$K$2:$K$1000,0)),"n/a") -> 69960 | E22: =IFERROR((D22-C22)/ABS(C22),"n/a") -> -0.16075863 | F22: down | G22: =IFERROR(MIN(5,MAX(1,3-(D22-C22)/ABS(C22)*5)),3) -> 3.8037931 | H22: 0.15 | I22: =G22*H22 -> 0.57056897
A23: Omnia | B23: Revenue (Rm) | C23: =IFERROR(INDEX(Dataset!$F$2:$F$1000,MATCH("Omnia|Revenue|FY2021",Dataset!$K$2:$K$1000,0)),"n/a") -> 16436 | D23: =IFERROR(INDEX(Dataset!$F$2:$F$1000,MATCH("Omnia|Revenue|FY2025",Dataset!$K$2:$K$1000,0)),"n/a") -> 22818 | E23: =IFERROR((D23-C23)/ABS(C23),"n/a") -> 0.38829399 | F23: up | G23: =IFERROR(MIN(5,MAX(1,3+(D23-C23)/ABS(C23)*5)),3) -> 4.9414699 | H23: 0.2 | I23: =G23*H23 -> 0.98829399
A24: Omnia | B24: Headline earnings per share (cents) | C24: =IFERROR(INDEX(Dataset!$F$2:$F$1000,MATCH("Omnia|Headline earnings per share|FY2021",Dataset!$K$2:$K$1000,0)),"n/a") -> 361 | D24: =IFERROR(INDEX(Dataset!$F$2:$F$1000,MATCH("Omnia|Headline earnings per share|FY2025",Dataset!$K$2:$K$1000,0)),"n/a") -> 704 | E24: =IFERROR((D24-C24)/ABS(C24),"n/a") -> 0.9501385 | F24: up | G24: =IFERROR(MIN(5,MAX(1,3+(D24-C24)/ABS(C24)*5)),3) -> 5 | H24: 0.25 | I24: =G24*H24 -> 1.25
A25: Omnia | B25: Recordable case rate | C25: =IFERROR(INDEX(Dataset!$F$2:$F$1000,MATCH("Omnia|Recordable case rate (RCR)|FY2024",Dataset!$K$2:$K$1000,0)),"n/a") -> 0.05 | D25: =IFERROR(INDEX(Dataset!$F$2:$F$1000,MATCH("Omnia|Recordable case rate (RCR)|FY2025",Dataset!$K$2:$K$1000,0)),"n/a") -> 0.2 | E25: =IFERROR((D25-C25)/ABS(C25),"n/a") -> 3 | F25: down | G25: =IFERROR(MIN(5,MAX(1,3-(D25-C25)/ABS(C25)*5)),3) -> 1 | H25: 0.1 | I25: =G25*H25 -> 0.1 | J25: FY2024 comparator = 0.05 (deteriorated)
A26: Omnia | B26: Renewable energy use (MWh) | C26: =IFERROR(INDEX(Dataset!$F$2:$F$1000,MATCH("Omnia|Renewable energy use|FY2024",Dataset!$K$2:$K$1000,0)),"n/a") -> 12976 | D26: =IFERROR(INDEX(Dataset!$F$2:$F$1000,MATCH("Omnia|Renewable energy use|FY2025",Dataset!$K$2:$K$1000,0)),"n/a") -> 20109 | E26: =IFERROR((D26-C26)/ABS(C26),"n/a") -> 0.54970715 | F26: up | G26: =IFERROR(MIN(5,MAX(1,3+(D26-C26)/ABS(C26)*5)),3) -> 5 | H26: 0.1 | I26: =G26*H26 -> 0.5 | J26: FY2024 comparator = 12,976
A27: Omnia | B27: COMPOSITE ESG-ADJUSTED FINANCIAL RISK SCORE | I27: =SUM(I21:I26)/SUM(H21:H26) -> 4.408863
A29: Sappi | B29: Sales (Rm, converted from USD) | C29: =IFERROR(INDEX(Dataset!$F$2:$F$1000,MATCH("Sappi|Sales|FY2021",Dataset!$K$2:$K$1000,0)),"n/a") -> 77898 | D29: =IFERROR(INDEX(Dataset!$F$2:$F$1000,MATCH("Sappi|Sales|FY2025",Dataset!$K$2:$K$1000,0)),"n/a") -> 96893 | E29: =IFERROR((D29-C29)/ABS(C29),"n/a") -> 0.24384451 | F29: up | G29: =IFERROR(MIN(5,MAX(1,3+(D29-C29)/ABS(C29)*5)),3) -> 4.2192226 | H29: 0.15 | I29: =G29*H29 -> 0.63288339 | J29: Converted from US$m using OECD/FRED annual average USD/ZAR rate per year; Rand-weakness over the period makes this figure more favourable than the original USD trend.
A30: Sappi | B30: Adjusted EBITDA (Rm, converted from USD) | C30: =IFERROR(INDEX(Dataset!$F$2:$F$1000,MATCH("Sappi|Adjusted EBITDA|FY2021",Dataset!$K$2:$K$1000,0)),"n/a") -> 7871 | D30: =IFERROR(INDEX(Dataset!$F$2:$F$1000,MATCH("Sappi|Adjusted EBITDA|FY2025",Dataset!$K$2:$K$1000,0)),"n/a") -> 8956 | E30: =IFERROR((D30-C30)/ABS(C30),"n/a") -> 0.1378478 | F30: up | G30: =IFERROR(MIN(5,MAX(1,3+(D30-C30)/ABS(C30)*5)),3) -> 3.689239 | H30: 0.25 | I30: =G30*H30 -> 0.92230974 | J30: Converted from US$m; up 13.9% in Rand terms over FY2021-FY2025, versus down 5.8% in the original USD figures, due to Rand depreciation over the period.
A31: Sappi | B31: Headline earnings/(loss) per share (cents, converted from USD) | C31: =IFERROR(INDEX(Dataset!$F$2:$F$1000,MATCH("Sappi|Headline earnings/(loss) per share|FY2021",Dataset!$K$2:$K$1000,0)),"n/a") -> 74 | D31: =IFERROR(INDEX(Dataset!$F$2:$F$1000,MATCH("Sappi|Headline earnings/(loss) per share|FY2025",Dataset!$K$2:$K$1000,0)),"n/a") -> -268 | E31: =IFERROR((D31-C31)/ABS(C31),"n/a") -> -4.6216216 | F31: up | G31: =IFERROR(MIN(5,MAX(1,3+(D31-C31)/ABS(C31)*5)),3) -> 1 | H31: 0.25 | I31: =G31*H31 -> 0.25 | J31: Converted from US cents; still turns negative in FY2025 in both currencies.
A32: Sappi | B32: Net asset value per share (cents, converted from USD) | C32: =IFERROR(INDEX(Dataset!$F$2:$F$1000,MATCH("Sappi|Net asset value per share|FY2021",Dataset!$K$2:$K$1000,0)),"n/a") -> 5193 | D32: =IFERROR(INDEX(Dataset!$F$2:$F$1000,MATCH("Sappi|Net asset value per share|FY2025",Dataset!$K$2:$K$1000,0)),"n/a") -> 6829 | E32: =IFERROR((D32-C32)/ABS(C32),"n/a") -> 0.31503948 | F32: up | G32: =IFERROR(MIN(5,MAX(1,3+(D32-C32)/ABS(C32)*5)),3) -> 4.5751974 | H32: 0.15 | I32: =G32*H32 -> 0.68627961 | J32: Converted from US cents; up 31.6% in Rand terms, versus up 8.8% in USD, due to Rand depreciation.
A33: Sappi | B33: Profit/(loss) for the year (Rm, converted from USD) | C33: =IFERROR(INDEX(Dataset!$F$2:$F$1000,MATCH("Sappi|Profit/(loss) for the year|FY2021",Dataset!$K$2:$K$1000,0)),"n/a") -> 192 | D33: =IFERROR(INDEX(Dataset!$F$2:$F$1000,MATCH("Sappi|Profit/(loss) for the year|FY2025",Dataset!$K$2:$K$1000,0)),"n/a") -> -3164 | E33: =IFERROR((D33-C33)/ABS(C33),"n/a") -> -17.479167 | F33: up | G33: =IFERROR(MIN(5,MAX(1,3+(D33-C33)/ABS(C33)*5)),3) -> 1 | H33: 0.2 | I33: =G33*H33 -> 0.2 | J33: Converted from US$m; still swings to a loss in FY2025 in both currencies.
A34: Sappi | B34: COMPOSITE ESG-ADJUSTED FINANCIAL RISK SCORE | I34: =SUM(I29:I33)/SUM(H29:H33) -> 2.6914727
A36: Sasol | B36: GHG reduction vs FY2017 baseline (%) | C36: n/a | D36: =IFERROR(INDEX(Dataset!$F$2:$F$1000,MATCH("Sasol|GHG emission reduction vs FY2017 baseline (International Chemicals)|FY2025",Dataset!$K$2:$K$1000,0)),"n/a") -> 23 | E36: =IFERROR((D36-C36)/ABS(C36),"n/a") -> n/a | F36: up | G36: =IFERROR(MIN(5,MAX(1,3+(D36-C36)/ABS(C36)*5)),3) -> 3 | H36: 0.3 | I36: =G36*H36 -> 0.9 | J36: Group target 30% by 2030; FY2025 figure is for International Chemicals only (p.85)
A37: Sasol | B37: Fatalities | C37: =IFERROR(INDEX(Dataset!$F$2:$F$1000,MATCH("Sasol|Fatalities|FY2022",Dataset!$K$2:$K$1000,0)),"n/a") -> 5 | D37: =IFERROR(INDEX(Dataset!$F$2:$F$1000,MATCH("Sasol|Fatalities|FY2024",Dataset!$K$2:$K$1000,0)),"n/a") -> 6 | E37: =IFERROR((D37-C37)/ABS(C37),"n/a") -> 0.2 | F37: down | G37: =IFERROR(MIN(5,MAX(1,3-(D37-C37)/ABS(C37)*5)),3) -> 2 | H37: 0.3 | I37: =G37*H37 -> 0.6 | J37: FY2022 vs FY2024 (most recent disclosed); FY2025 not yet extracted
A38: Sasol | B38: Recordable case rate | C38: n/a | D38: =IFERROR(INDEX(Dataset!$F$2:$F$1000,MATCH("Sasol|Recordable case rate|FY2024",Dataset!$K$2:$K$1000,0)),"n/a") -> 0.25 | E38: =IFERROR((D38-C38)/ABS(C38),"n/a") -> n/a | F38: down | G38: =IFERROR(MIN(5,MAX(1,3-(D38-C38)/ABS(C38)*5)),3) -> 3 | H38: 0.2 | I38: =G38*H38 -> 0.6 | J38: FY2024 only; time series incomplete
A39: Sasol | B39: External turnover (Rm) | C39: =IFERROR(INDEX(Dataset!$F$2:$F$1000,MATCH("Sasol|External turnover|FY2021",Dataset!$K$2:$K$1000,0)),"n/a") -> 201910 | D39: =IFERROR(INDEX(Dataset!$F$2:$F$1000,MATCH("Sasol|External turnover|FY2025",Dataset!$K$2:$K$1000,0)),"n/a") -> 249096 | E39: =IFERROR((D39-C39)/ABS(C39),"n/a") -> 0.23369818 | F39: up | G39: =IFERROR(MIN(5,MAX(1,3+(D39-C39)/ABS(C39)*5)),3) -> 4.1684909 | H39: 0.15 | I39: =G39*H39 -> 0.62527364 | J39: Sourced from Sasol's audited SENS/PRNewswire results announcements.
A40: Sasol | B40: Adjusted EBITDA (Rm) | C40: =IFERROR(INDEX(Dataset!$F$2:$F$1000,MATCH("Sasol|Adjusted EBITDA|FY2021",Dataset!$K$2:$K$1000,0)),"n/a") -> 48420 | D40: =IFERROR(INDEX(Dataset!$F$2:$F$1000,MATCH("Sasol|Adjusted EBITDA|FY2025",Dataset!$K$2:$K$1000,0)),"n/a") -> 51764 | E40: n/a | F40: up | G40: 3 | H40: 0.2 | I40: =G40*H40 -> 0.6 | J40: Now sourced from Sasol's audited SENS/PRNewswire results announcements (external to the integrated reports) since no 5-year table exists in the integrated reports themselves.
A41: Sasol | B41: COMPOSITE ESG-ADJUSTED FINANCIAL RISK SCORE | I41: =SUM(I36:I40)/SUM(H36:H40) -> 2.8915423
A44: Summary: composite score by company (5 = strongest ESG-adjusted position, 1 = weakest)
A45: AECI | B45: =I11 -> 4.2363187
A46: ArcelorMittal SA | B46: =I19 -> 2.5769808
A47: Omnia | B47: =I27 -> 4.408863
...
