Workbook

Sheet Data Dictionary
A1: Data Dictionary: ESG-Financial Decision Intelligence Dataset
A2: APFA802 Major Project -- Beyond the Report: Transforming Integrated Reporting Data into Decision Intelligence
A4: This dataset covers 5 JSE-listed companies from related basic-materials/industrial sectors (chemicals, mining services, steel, construction materials and energy) over FY2021-FY2025 (25 company-year observations), compiled entirely from each company's own published Integrated Annual Report (IAR). Every observation is traceable to a specific page in a specific company's specific-year IAR -- see the 'Source Citations' sheet for the full page-by-page reference table (407 citation rows covering every extracted variable). All monetary values were verified, company by company and year by year, to be presented in South African Rand (ZAR) in the source document before inclusion, so that cross-company and cross-time comparisons in this workbook are on a like-for-like currency basis. The dataset was independently re-verified against the primary-source IARs a second time after initial extraction; this second pass corrected 8 transcription errors (documented in the Source Citations sheet's Status column as CORRECTED), most significantly a board-gender-diversity figure for one company-year that had been drawn from the wrong line of a source chart.
A6: Variable | B6: Unit / Scale | C6: Measurement Definition | D6: Source (IAR section) | E6: Six Capitals / Category | F6: Known Limitations
A7: company / ticker / sector / fy | B7: text / text / text / year | C7: Company legal name, JSE share code, sector classification used in this project, and fiscal year (Afrimat, AECI, ArcelorMittal SA, Sasol: FYE 30 June or 31 Dec as applicable; OMNIA: FYE 31 March). | D7: IAR cover page / company profile | E7: Identification | F7: OMNIA's 'FY2021' covers the year ended 31 March 2021, not calendar 2021 -- a lag of up to 9 months versus the other four companies' year-ends is possible in any single comparison and is disclosed.
A8: currency | B8: text (ZAR) | C8: Reporting currency confirmed from the actual statement column headers in each company's own IAR for each year (not assumed). | D8: Statement of financial position / income statement headers | E8: Data quality control | F8: All 25 observations confirmed Rand; no conversion was required or applied.
A9: revenue_zar_m | B9: R million | C9: Total revenue / turnover for the fiscal year, as reported in the summarised or full income statement. | D9: Financial highlights / income statement | E9: Financial capital | F9: None identified.
A10: operating_profit_zar_m | B10: R million | C10: Operating profit (EBIT) or nearest disclosed equivalent (e.g. profit/(loss) from operations); ArcelorMittal and Sasol figures include the effect of impairments/remeasurement items where these form part of the reported operating result. | D10: Financial highlights / income statement | E10: Financial capital | F10: AECI FY2024-FY2025: single EBIT line not disclosed in the Integrated Report; left blank rather than estimated (EBITDA was disclosed but is not the same measure and was not substituted).
A11: net_income_zar_m | B11: R million | C11: Profit/(loss) for the year attributable to owners of the parent. | D11: Financial highlights / income statement | E11: Financial capital | F11: AECI FY2025: not disclosed as a Rand figure in the Integrated Report (only a qualitative EPS growth statement was given); left blank.
A12: total_assets_zar_m | B12: R million | C12: Total assets per the statement of financial position. | D12: Statement of financial position | E12: Financial capital | F12: AECI: not disclosed in any of the 5 Integrated Reports, which are strategic/sustainability documents rather than the full Annual Financial Statements; left blank for all 5 AECI years rather than sourced from an unverified external document.
A13: total_equity_zar_m | B13: R million | C13: Total equity (owners' equity plus non-controlling interests where disclosed as a combined figure). | D13: Statement of financial position | E13: Financial capital | F13: ArcelorMittal SA FY2025 total equity is negative (-R429m), reflecting accumulated losses exceeding contributed capital; reported as-is, not treated as an error.
A14: total_debt_zar_m | B14: R million | C14: Total interest-bearing borrowings (current plus non-current), or the company's own stated 'total debt' commentary figure where a summarised balance sheet does not break this out separately (Sasol). | D14: Statement of financial position / CFO commentary | E14: Financial capital | F14: Definitions are not perfectly uniform across companies (e.g. Sasol's stated 'total debt' may net certain items differently from a strict current+non-current borrowings sum); used consistently within each company's own time series.
A15: eps_cents | B15: SA cents per share | C15: Basic earnings/(loss) per share as reported. | D15: Income statement / financial highlights | E15: Financial capital | F15: ArcelorMittal SA: basic EPS not disclosed in any of the 5 Integrated Reports (only Headline EPS, a JSE-standard adjusted measure); left blank.
A16: scope1_tco2e / scope2_tco2e | B16: tonnes CO2-equivalent | C16: Direct (Scope 1) and indirect energy-related (Scope 2) greenhouse gas emissions for the reporting year, per the company's own GHG inventory (typically assured under ISO 14064 or similar). | D16: Sustainability / environment section, GHG emissions table | E16: Natural capital | F16: ArcelorMittal SA and Sasol do not disclose a separate absolute Scope 1 / Scope 2 split in every year's own report (ArcelorMittal discloses only combined absolute Mt plus per-tonne intensity ratios; Sasol's split is only available retrospectively in later assurance tables and was therefore left blank for internal consistency) -- see total_ghg_tco2e instead, which is available for all 25 observations.
A17: total_ghg_tco2e | B17: tonnes CO2-equivalent | C17: Combined Scope 1 + Scope 2 GHG emissions for the year, as disclosed (directly, or as the sum of separately disclosed Scope 1 and Scope 2 figures). This is the primary cross-company-comparable emissions variable used throughout the analysis. | D17: Sustainability / environment section | E17: Natural capital | F17: Sasol and ArcelorMittal figures were converted to tonnes from kilotonnes/megatonnes as originally disclosed; conversion factors documented in the Raw Data sheet notes.
... A25: csi_spend_zar_m | B25: R million | C25: Corporate social investment / socio-economic development spend for the year (a common, comparable definition across all five companies' own disclosures). | D25: Social and relationship capital section | E25: Social and relationship capital | F25: AECI FY2021: CSI spend not stated as a Rand figure in the FY2021 report itself; sourced from the FY2022 report's own comparative disclosure of the FY2021 figure.

Sheet Raw Data
A1: Company | B1: Ticker | C1: Sector | D1: FY | E1: Currency | F1: Revenue (Rm) | G1: Operating Profit (Rm) | H1: Net Income (Rm) | I1: Total Assets (Rm) | J1: Total Equity (Rm) | K1: Total Debt (Rm) | L1: EPS (cents) | M1: Scope 1 (tCO2e) | N1: Scope 2 (tCO2e) | O1: Total GHG (tCO2e) | P1: Water (m3) | Q1: Employees | R1: Safety Metric | S1: Safety Value | T1: Fatalities | U1: B-BBEE Level | V1: Board Women (%) | W1: GHG Target (%) | X1: GHG Target Year | Y1: CSI Spend (Rm)
A2: Afrimat Limited | B2: AFT | C2: Construction Materials & Mining | D2: 2021 | E2: ZAR | F2: 3693.759 | G2: 886.291 | H2: 601.254 | I2: 4455.32 | J2: 2258.407 | K2: 513.901 | L2: 444.1 | M2: 89662 | N2: 45265.8 | O2: 134927.8 | P2: 518029 | Q2: 2625 | R2: LTIFR | S2: 0.61 | U2: 3 | V2: 8 | Y2: 25.4
A3: Afrimat Limited | B3: AFT | C3: Construction Materials & Mining | D3: 2022 | E3: ZAR | F3: 4680.078 | G3: 1108.911 | H3: 772.714 | I3: 5046.297 | J3: 3007.2 | K3: 643.826 | L3: 560.7 | M3: 125619.9 | N3: 44569.8 | O3: 170189.7 | P3: 810024 | Q3: 2511 | R3: LTIFR | S3: 0.58 | U3: 3 | V3: 15 | W3: 32 | X3: 2030 | Y3: 38
A4: Afrimat Limited | B4: AFT | C4: Construction Materials & Mining | D4: 2023 | E4: ZAR | F4: 4908.238 | G4: 961.561 | H4: 661.32 | I4: 5681.132 | J4: 3849.014 | K4: 312.576 | L4: 457.1 | M4: 112789.6 | N4: 50194.3 | O4: 162983.9 | P4: 1384706 | Q4: 2668 | R4: LTIFR | S4: 0.34 | U4: 2 | V4: 17 | W4: 32 | X4: 2030 | Y4: 50.4
A5: Afrimat Limited | B5: AFT | C5: Construction Materials & Mining | D5: 2024 | E5: ZAR | F5: 6083.28 | G5: 1152.365 | H5: 781.776 | I5: 6748.527 | J5: 4563.041 | K5: 557.125 | L5: 520.3 | M5: 127915.8 | N5: 49349.5 | O5: 177265.3 | P5: 1586935 | Q5: 2755 | R5: LTIFR | S5: 0.29 | U5: 2 | V5: 17 | W5: 32 | X5: 2030 | Y5: 73.6
A6: Afrimat Limited | B6: AFT | C6: Construction Materials & Mining | D6: 2025 | E6: ZAR | F6: 8317.766 | G6: 477.735 | H6: 95.562 | I6: 9203.294 | J6: 4388.26 | K6: 1859.267 | L6: 63 | M6: 154217 | N6: 49049 | O6: 203266 | P6: 1922937 | Q6: 3829 | R6: LTIFR | S6: 0.27 | U6: 2 | V6: 17 | X6: 2050 | Y6: 62.3
A7: AECI Limited | B7: AFE | C7: Chemicals | D7: 2021 | E7: ZAR | F7: 26053 | G7: 2052 | H7: 1210 | J7: 11589 | K7: 2760 | L7: 1125 | M7: 266291 | N7: 235043 | O7: 501334 | P7: 1755929 | Q7: 7030 | R7: TRIR | S7: 0.23 | T7: 0 | U7: 3 | V7: 36 | X7: 2050 | Y7: 34.8
A8: AECI Limited | B8: AFE | C8: Chemicals | D8: 2022 | E8: ZAR | F8: 35583 | G8: 2047 | H8: 956 | J8: 11800 | K8: 5300 | L8: 878 | M8: 267919 | N8: 225882 | O8: 493801 | P8: 1793455 | Q8: 7168 | R8: TRIR | S8: 0.15 | T8: 0 | U8: 3 | V8: 40 | X8: 2050 | Y8: 36.2
A9: AECI Limited | B9: AFE | C9: Chemicals | D9: 2023 | E9: ZAR | F9: 37500 | G9: 2571 | H9: 1180 | J9: 12400 | K9: 4300 | L9: 1112 | M9: 213711 | N9: 226177 | O9: 439888 | P9: 1678865 | Q9: 7189 | R9: TRIR | S9: 0.35 | T9: 2 | U9: 3 | V9: 50 | X9: 2050 | Y9: 40
A10: AECI Limited | B10: AFE | C10: Chemicals | D10: 2024 | E10: ZAR | F10: 33598 | H10: -255 | J10: 12100 | K10: 3738 | L10: -268 | O10: 416337 | P10: 1638050 | Q10: 6938 | R10: TRIR | S10: 0.31 | T10: 0 | U10: 3 | V10: 44 | W10: 10 | X10: 2025 | Y10: 28.5
A11: AECI Limited | B11: AFE | C11: Chemicals | D11: 2025 | E11: ZAR | F11: 32183 | G11: 1530 | J11: 11600 | K11: 465 | M11: 162998 | N11: 202502 | O11: 365500 | P11: 1553625 | Q11: 5459 | R11: TRIR | S11: 0.2 | T11: 0 | V11: 50 | W11: 15 | X11: 2030 | Y11: 33
A12: ArcelorMittal South Africa | B12: AMS | C12: Steel & Metals | D12: 2021 | E12: ZAR | F12: 39708 | G12: 7976 | H12: 6625 | I12: 29093 | J12: 9053 | K12: 5910 | L12: 615 | O12: 8410000 | P12: 12020708 | Q12: 7133 | R12: LTIFR | S12: 0.98 | T12: 6 | U12: 8 | V12: 45 | W12: 25 | X12: 2030 | Y12: 15.5
A13: ArcelorMittal South Africa | B13: AMS | C13: Steel & Metals | D13: 2022 | E13: ZAR | F13: 40771 | G13: 3499 | H13: 2634 | I13: 30001 | J13: 11675 | K13: 6200 | L13: 234 | O13: 8350000 | P13: 11418318 | Q13: 6450 | R13: LTIFR | S13: 0.87 | T13: 2 | U13: 6 | V13: 42 | W13: 25 | X13: 2030 | Y13: 16.7
A14: ArcelorMittal South Africa | B14: AMS | C14: Steel & Metals | D14: 2023 | E14: ZAR | F14: 41637 | G14: -2937 | H14: -3920 | I14: 29110 | J14: 7799 | K14: 6700 | L14: -170 | O14: 9520000 | P14: 10862243 | Q14: 6449 | R14: LTIFR | S14: 0.77 | T14: 1 | U14: 6 | V14: 30 | W14: 25 | X14: 2030 | Y14: 16.5
A15: ArcelorMittal South Africa | B15: AMS | C15: Steel & Metals | D15: 2024 | E15: ZAR | F15: 38596 | G15: -4447 | H15: -5839 | I15: 24941 | J15: 1963 | K15: 8705 | L15: -458 | O15: 8850000 | P15: 11613459 | Q15: 6108 | R15: LTIFR | S15: 1.13 | T15: 1 | U15: 7 | V15: 29 | W15: 25 | X15: 2030 | Y15: 16.3
A16: ArcelorMittal South Africa | B16: AMS | C16: Steel & Metals | D16: 2025 | E16: ZAR | F16: 32291 | G16: -2043 | H16: -3012 | I16: 21014 | J16: -429 | K16: 9126 | L16: -301 | O16: 7510000 | P16: 12622339 | Q16: 5569 | R16: LTIFR | S16: 0.62 | T16: 1 | U16: 4 | V16: 25 | W16: 10 | X16: 2030 | Y16: 16.3
A17: Omnia Holdings Limited | B17: OMN | C17: Chemicals & Agriculture | D17: 2021 | E17: ZAR | F17: 17790 | G17: 1205 | H17: 658 | I17: 14853 | J17: 9739 | K17: 66 | L17: 394 | M17: 178139 | N17: 83361 | O17: 261500 | P17: 1978000 | Q17: 4200 | R17: RCR | S17: 0.35 | T17: 0 | U17: 2 | V17: 18 | W17: 25 | X17: 2030 | Y17: 24.3
A18: Omnia Holdings Limited | B18: OMN | C18: Chemicals & Agriculture | D18: 2022 | E18: ZAR | F18: 21437 | G18: 1597 | H18: 1093 | I18: 16011 | J18: 10018 | K18: 52 | L18: 653 | M18: 252803 | N18: 84105 | O18: 336908 | P18: 1861000 | Q18: 4010 | R18: RCR | S18: 0.21 | T18: 2 | U18: 2 | V18: 18 | W18: 25 | X18: 2030 | Y18: 28.7
A19: Omnia Holdings Limited | B19: OMN | C19: Chemicals & Agriculture | D19: 2023 | E19: ZAR | F19: 26572 | G19: 1899 | H19: 1169 | I19: 16835 | J19: 10255 | K19: 43 | L19: 692 | M19: 110774 | N19: 76828 | O19: 187602 | P19: 1678000 | Q19: 3869 | R19: LTIFR | S19: 0.1 | T19: 0 | U19: 2 | V19: 30 | X19: 2050 | Y19: 46
A20: Omnia Holdings Limited | B20: OMN | C20: Chemicals & Agriculture | D20: 2024 | E20: ZAR | F20: 22219 | G20: 1703 | H20: 1160 | I20: 17526 | J20: 10820 | K20: 149 | L20: 705 | M20: 81716 | N20: 75043 | O20: 156759 | P20: 1588000 | Q20: 3756 | R20: LTIFR | S20: 0.03 | T20: 0 | U20: 2 | V20: 30 | X20: 2050 | Y20: 49.8
A21: Omnia Holdings Limited | B21: OMN | C21: Chemicals & Agriculture | D21: 2025 | E21: ZAR | F21: 22818 | G21: 1698 | H21: 1142 | I21: 17177 | J21: 10428 | K21: 159 | L21: 692 | M21: 70437 | N21: 69960 | O21: 140397 | P21: 1588000 | Q21: 3803 | R21: LTIFR | S21: 0.17 | T21: 0 | U21: 2 | V21: 30 | W21: 45 | X21: 2030 | Y21: 59.5
A22: Sasol Limited | B22: SOL | C22: Energy & Chemicals | D22: 2021 | E22: ZAR | F22: 201910 | G22: 16619 | H22: 9032 | I22: 360743 | J22: 152471 | K22: 102900 | L22: 1457 | O22: 67102000 | P22: 138050000 | Q22: 28725 | R22: RCR | S22: 0.26 | T22: 2 | U22: 4 | V22: 38 | W22: 30 | X22: 2030 | Y22: 526.2
A23: Sasol Limited | B23: SOL | C23: Energy & Chemicals | D23: 2022 | E23: ZAR | F23: 275738 | G23: 61417 | H23: 38956 | I23: 419548 | J23: 193197 | K23: 105100 | L23: 6234 | O23: 63572000 | P23: 132686000 | Q23: 28279 | R23: RCR | S23: 0.27 | T23: 5 | U23: 3 | V23: 46 | W23: 30 | X23: 2030 | Y23: 743.3
A24: Sasol Limited | B24: SOL | C24: Energy & Chemicals | D24: 2023 | E24: ZAR | F24: 289696 | G24: 21520 | H24: 8799 | I24: 433838 | J24: 201524 | K24: 124300 | L24: 1400 | O24: 64392000 | P24: 114122000 | Q24: 28657 | R24: RCR | S24: 0.27 | T24: 2 | U24: 3 | V24: 42 | W24: 30 | X24: 2030 | Y24: 857.3
A25: Sasol Limited | B25: SOL | C25: Energy & Chemicals | D25: 2024 | E25: ZAR | F25: 275111 | G25: -27305 | H25: -44271 | I25: 364980 | J25: 147427 | K25: 117800 | L25: -6994 | O25: 64819000 | P25: 128557000 | Q25: 27678 | R25: RCR | S25: 0.25 | T25: 5 | U25: 2 | V25: 50 | W25: 30 | X25: 2030 | Y25: 693.2
A26: Sasol Limited | B26: SOL | C26: Energy & Chemicals | D26: 2025 | E26: ZAR | F26: 249096 | G26: 18819 | H26: 6767 | I26: 359555 | J26: 157611 | K26: 103300 | L26: 1060 | O26: 58728000 | P26: 127758480 | Q26: 27107 | R26: RCR | S26: 0.25 | T26: 1 | U26: 2 | V26: 45 | W26: 30 | X26: 2030 | Y26: 663.3
A29: Notes on data completeness and unit conversions:
A30: • All 25 observations were verified as presented in South African Rand in the underlying Integrated Annual Report before inclusion (see Data Dictionary sheet).
A31: • Water was converted to a common cubic-metre (m3) basis: ArcelorMittal's kilolitres require no conversion (1 kl = 1 m3); OMNIA's megalitres were multiplied by 1,000; Sasol's '000 m3 figures were multiplied by 1,000.
A32: • Total GHG (Scope 1+2) for Sasol was converted from kilotonnes to tonnes (x1,000); for ArcelorMittal SA, from megatonnes to tonnes (x1,000,000), since ArcelorMittal does not disclose a separate absolute Scope 1/Scope 2 split in its own reports.
A33: • Blank cells are missing data (not disclosed in the source IAR for that company-year), not zero, and are excluded pairwise from every calculation in the Ratios, Descriptive Stats, Correlation and ESG Index sheets.
A34: • Full per-company, per-year page citations for every extracted variable are recorded in the 'Source Citations' sheet of this workbook (407 rows); the Data Dictionary sheet above records source section and known limitations at the variable level.

Sheet Source Citations
A1: Source Citations: Page-Level Traceability of Every Extracted Observation
A2: This sheet records the page number, IAR section, and verification status for every extracted variable used in this project (407 citation rows across 5 companies x 5 fiscal years). It was compiled by an independent second-pass re-verification: each company's full set of Integrated Annual Reports was re-read against the dataset a second time, page by page, after initial extraction. Status meanings -- CONFIRMED: value matches the cited page exactly; DERIVED: value calculated or combined from disclosures on the cited page(s) (e.g. summing separately disclosed components); RESTATED: the cited-year IAR's own figure was later restated in a subsequent year's IAR, and the restated figure is noted; CORRECTED: an error was found in the originally recorded value during this second-pass verification and has been corrected in the dataset (see Note column for what changed); GENUINELY ABSENT: the field is confirmed, after exhaustive search of the source document, to not be disclosed for that company-year (left blank in the dataset rather than estimated).
A4: Company | B4: FY | C4: Variable | D4: Page Reference | E4: IAR Section | F4: Status | G4: Note
A5: Afrimat Limited | B5: 2021 | C5: revenue_zar_m | D5: 25 | E5: Five-Year Review | F5: CONFIRMED
A6: Afrimat Limited | B6: 2021 | C6: operating_profit_zar_m | D6: 25 | E6: Five-Year Review | F6: CONFIRMED
A7: Afrimat Limited | B7: 2021 | C7: net_income_zar_m | D7: 72 | E7: Statement of Profit or Loss | F7: CONFIRMED
A8: Afrimat Limited | B8: 2021 | C8: total_assets_zar_m | D8: 25 | E8: Five-Year Review | F8: CONFIRMED
A9: Afrimat Limited | B9: 2021 | C9: total_equity_zar_m | D9: 25 | E9: Five-Year Review | F9: CONFIRMED
A10: Afrimat Limited | B10: 2021 | C10: total_debt_zar_m | D10: 95 | E10: Note - Borrowings | F10: CONFIRMED
A11: Afrimat Limited | B11: 2021 | C11: eps_cents | D11: 25 | E11: Five-Year Review | F11: CONFIRMED
A12: Afrimat Limited | B12: 2021 | C12: scope1_tco2e | D12: 42 | E12: Environmental Responsibility - GHG table | F12: CONFIRMED
A13: Afrimat Limited | B13: 2021 | C13: scope2_tco2e | D13: 42 | E13: Environmental Responsibility - GHG table | F13: CONFIRMED
A14: Afrimat Limited | B14: 2021 | C14: water_m3 | D14: 42 | E14: Environmental Responsibility - Water | F14: CONFIRMED
A15: Afrimat Limited | B15: 2021 | C15: employees | D15: 25 | E15: Five-Year Review | F15: CONFIRMED
A16: Afrimat Limited | B16: 2021 | C16: safety_value | D16: 25 | E16: Five-Year Review | F16: CONFIRMED
... A44: Afrimat Limited | B44: 2023 | C44: safety_value | D44: 28 | E44: Five-Year Review | F44: CONFIRMED
A45: Afrimat Limited | B45: 2023 | C45: bbee_level | D45: 9 | E45: Value-Creation infographic | F45: RESTATED | G45: FY2023 IAR itself states Level 3; the FY2024 IAR's comparative column later restates 2023 to Level 2 (lagged verification cycle). Dataset uses the later-verified figure; cite FY2024 IAR p.9.
A46: Afrimat Limited | B46: 2023 | C46: board_women_pct | D46: 35 | E46: Directorate - Board Demographics | F46: CONFIRMED
A47: Afrimat Limited | B47: 2024 | C47: revenue_zar_m | D47: 28 | E47: Five-Year Review | F47: CONFIRMED
A48: Afrimat Limited | B48: 2024 | C48: operating_profit_zar_m | D48: 28 | E48: Five-Year Review | F48: CONFIRMED
A49: Afrimat Limited | B49: 2024 | C49: net_income_zar_m | D49: 89 | E49: Statement of Profit or Loss | F49: CONFIRMED
A50: Afrimat Limited | B50: 2024 | C50: total_assets_zar_m | D50: 28 | E50: Five-Year Review | F50: CONFIRMED
A51: Afrimat Limited | B51: 2024 | C51: total_equity_zar_m | D51: 28 | E51: Five-Year Review | F51: CONFIRMED
A52: Afrimat Limited | B52: 2024 | C52: total_debt_zar_m | D52: 118 | E52: Note - Borrowings | F52: CONFIRMED
A53: Afrimat Limited | B53: 2024 | C53: eps_cents | D53: 28 | E53: Five-Year Review | F53: CONFIRMED
A54: Afrimat Limited | B54: 2024 | C54: scope1_tco2e | D54: 49 | E54: Environmental Responsibility - GHG table | F54: CONFIRMED
A55: Afrimat Limited | B55: 2024 | C55: scope2_tco2e | D55: 49 | E55: Environmental Responsibility - GHG table | F55: CONFIRMED
A56: Afrimat Limited | B56: 2024 | C56: water_m3 | D56: 48 | E56: Environmental Responsibility - Water | F56: CONFIRMED
A57: Afrimat Limited | B57: 2024 | C57: employees | D57: 28 | E57: Five-Year Review | F57: CONFIRMED
... A82: Afrimat Limited | B82: 2024 | C82: ghg_target_pct | D82: 47 | E82: Environmental Responsibility | F82: CONFIRMED
A83: Afrimat Limited | B83: 2025 | C83: ghg_target_year | D83: 48 | E83: Environmental Responsibility | F83: CONFIRMED | G83: No % stated for FY2025; target under review following the Lafarge acquisition; only the 2050 carbon-neutrality goal is restated.
A84: Afrimat Limited | B84: 2021 | C84: fatalities | D84: 1 | E84: Front-cover safety statement | F84: GENUINELY ABSENT (qualitative only) | G84: IAR states "No fatalities for nine consecutive years" rather than an annual occupational count; recorded as blank, not zero, per project convention. Note: 6 (FY21) and a cumulative 8 (FY22) COVID-19 fatalities are separately disclosed (p.43/p.51) but are non-occupational and excluded from this field.
A85: Afrimat Limited | B85: 2022 | C85: fatalities | D85: 1 | E85: Front-cover safety statement | F85: GENUINELY ABSENT (qualitative only) | G85: IAR states "No fatalities for ten consecutive years" rather than an annual occupational count; recorded as blank, not zero, per project convention. Note: 6 (FY21) and a cumulative 8 (FY22) COVID-19 fatalities are separately disclosed (p.43/p.51) but are non-occupational and excluded from this field.
A86: Afrimat Limited | B86: 2023 | C86: fatalities | D86: 1 | E86: Front-cover safety statement | F86: GENUINELY ABSENT (qualitative only) | G86: IAR states "No fatalities for 11 consecutive years" rather than an annual occupational count; recorded as blank, not zero, per project convention. Note: 6 (FY21) and a cumulative 8 (FY22) COVID-19 fatalities are separately disclosed (p.43/p.51) but are non-occupational and excluded from this field.
A87: Afrimat Limited | B87: 2024 | C87: fatalities | D87: - | E87: - | F87: GENUINELY ABSENT | G87: The words fatal/fatality do not appear anywhere in this year's IAR; the fatality-free-streak disclosure used in FY2021-23 was discontinued from FY2024 onward. Recorded as blank (data gap), not zero.
A88: Afrimat Limited | B88: 2025 | C88: fatalities | D88: - | E88: - | F88: GENUINELY ABSENT | G88: The words fatal/fatality do not appear anywhere in this year's IAR; the fatality-free-streak disclosure used in FY2021-23 was discontinued from FY2024 onward. Recorded as blank (data gap), not zero.
A89: AECI Limited | B89: 2021 | C89: revenue_zar_m | D89: 22 | E89: From our CFO - Performance summary | F89: CONFIRMED
A90: AECI Limited | B90: 2021 | C90: operating_profit_zar_m | D90: 21-22 | E90: From our CFO - Financial performance | F90: CONFIRMED
A91: AECI Limited | B91: 2021 | C91: net_income_zar_m | D91: 41 (FY2022 IAR) | E91: FY2022 CFO performance summary, FY2021 comparative column | F91: CONFIRMED (comparative) | G91: Not disclosed as a single line in the FY2021 IAR itself (only EBITDA/EBIT/EPS given); recovered from FY2022 IAR's own comparative column.
A92: AECI Limited | B92: 2021 | C92: total_equity_zar_m | D92: 7 | E92: Our value-creating business model | F92: CONFIRMED
...

Sheet Ratios
A1: Company | B1: Ticker | C1: Sector | D1: FY | E1: Operating Margin (%) | F1: Net Margin (%) | G1: ROA (%) | H1: ROE (%) | I1: Debt-to-Equity | J1: GHG Intensity (tCO2e/Rm Rev) | K1: Water Intensity (m3/Rm Rev) | L1: GHG per Employee (tCO2e) | M1: CSI Intensity (% Revenue) | N1: Revenue per Employee (Rm)
A2: ='Raw Data'!A2 -> Afrimat Limited | B2: ='Raw Data'!B2 -> AFT | C2: ='Raw Data'!C2 -> Construction Materials & Mining | D2: ='Raw Data'!D2 -> 2021 | E2: =IFERROR('Raw Data'!G2/'Raw Data'!F2*100,"") -> 23.994283 | F2: =IFERROR('Raw Data'!H2/'Raw Data'!F2*100,"") -> 16.277564 | G2: =IFERROR('Raw Data'!H2/'Raw Data'!I2*100,"") -> 13.495192 | H2: =IFERROR('Raw Data'!H2/'Raw Data'!J2*100,"") -> 26.622925 | I2: =IFERROR('Raw Data'!K2/'Raw Data'!J2,"") -> 0.22755022 | J2: =IFERROR('Raw Data'!O2/'Raw Data'!F2,"") -> 36.528588 | K2: =IFERROR('Raw Data'!P2/'Raw Data'!F2,"") -> 140.2444 | L2: =IFERROR('Raw Data'!O2/'Raw Data'!Q2,"") -> 51.401067 | M2: =IFERROR('Raw Data'!Y2/'Raw Data'!F2*100,"") -> 0.68764638 | N2: =IFERROR('Raw Data'!F2/'Raw Data'!Q2,"") -> 1.4071463
A3: ='Raw Data'!A3 -> Afrimat Limited | B3: ='Raw Data'!B3 -> AFT | C3: ='Raw Data'!C3 -> Construction Materials & Mining | D3: ='Raw Data'!D3 -> 2022 | E3: =IFERROR('Raw Data'!G3/'Raw Data'!F3*100,"") -> 23.694285 | F3: =IFERROR('Raw Data'!H3/'Raw Data'!F3*100,"") -> 16.510708 | G3: =IFERROR('Raw Data'!H3/'Raw Data'!I3*100,"") -> 15.312495 | H3: =IFERROR('Raw Data'!H3/'Raw Data'!J3*100,"") -> 25.695464 | I3: =IFERROR('Raw Data'!K3/'Raw Data'!J3,"") -> 0.21409484 | J3: =IFERROR('Raw Data'!O3/'Raw Data'!F3,"") -> 36.364714 | K3: =IFERROR('Raw Data'!P3/'Raw Data'!F3,"") -> 173.07917 | L3: =IFERROR('Raw Data'!O3/'Raw Data'!Q3,"") -> 67.777658 | M3: =IFERROR('Raw Data'!Y3/'Raw Data'!F3*100,"") -> 0.81195228 | N3: =IFERROR('Raw Data'!F3/'Raw Data'!Q3,"") -> 1.8638303
A4: ='Raw Data'!A4 -> Afrimat Limited | B4: ='Raw Data'!B4 -> AFT | C4: ='Raw Data'!C4 -> Construction Materials & Mining | D4: ='Raw Data'!D4 -> 2023 | E4: =IFERROR('Raw Data'!G4/'Raw Data'!F4*100,"") -> 19.590757 | F4: =IFERROR('Raw Data'!H4/'Raw Data'!F4*100,"") -> 13.473674 | G4: =IFERROR('Raw Data'!H4/'Raw Data'!I4*100,"") -> 11.640638 | H4: =IFERROR('Raw Data'!H4/'Raw Data'!J4*100,"") -> 17.181543 | I4: =IFERROR('Raw Data'!K4/'Raw Data'!J4,"") -> 0.081209369 | J4: =IFERROR('Raw Data'!O4/'Raw Data'!F4,"") -> 33.206193 | K4: =IFERROR('Raw Data'!P4/'Raw Data'!F4,"") -> 282.11876 | L4: =IFERROR('Raw Data'!O4/'Raw Data'!Q4,"") -> 61.088418 | M4: =IFERROR('Raw Data'!Y4/'Raw Data'!F4*100,"") -> 1.0268451 | N4: =IFERROR('Raw Data'!F4/'Raw Data'!Q4,"") -> 1.8396694
A5: ='Raw Data'!A5 -> Afrimat Limited | B5: ='Raw Data'!B5 -> AFT | C5: ='Raw Data'!C5 -> Construction Materials & Mining | D5: ='Raw Data'!D5 -> 2024 | E5: =IFERROR('Raw Data'!G5/'Raw Data'!F5*100,"") -> 18.943152 | F5: =IFERROR('Raw Data'!H5/'Raw Data'!F5*100,"") -> 12.851225 | G5: =IFERROR('Raw Data'!H5/'Raw Data'!I5*100,"") -> 11.584395 | H5: =IFERROR('Raw Data'!H5/'Raw Data'!J5*100,"") -> 17.132785 | I5: =IFERROR('Raw Data'!K5/'Raw Data'!J5,"") -> 0.12209511 | J5: =IFERROR('Raw Data'!O5/'Raw Data'!F5,"") -> 29.139757 | K5: =IFERROR('Raw Data'!P5/'Raw Data'!F5,"") -> 260.86831 | L5: =IFERROR('Raw Data'!O5/'Raw Data'!Q5,"") -> 64.343122 | M5: =IFERROR('Raw Data'!Y5/'Raw Data'!F5*100,"") -> 1.2098736 | N5: =IFERROR('Raw Data'!F5/'Raw Data'!Q5,"") -> 2.2080871
A6: ='Raw Data'!A6 -> Afrimat Limited | B6: ='Raw Data'!B6 -> AFT | C6: ='Raw Data'!C6 -> Construction Materials & Mining | D6: ='Raw Data'!D6 -> 2025 | E6: =IFERROR('Raw Data'!G6/'Raw Data'!F6*100,"") -> 5.7435494 | F6: =IFERROR('Raw Data'!H6/'Raw Data'!F6*100,"") -> 1.1488902 | G6: =IFERROR('Raw Data'!H6/'Raw Data'!I6*100,"") -> 1.0383456 | H6: =IFERROR('Raw Data'!H6/'Raw Data'!J6*100,"") -> 2.1776741 | I6: =IFERROR('Raw Data'!K6/'Raw Data'!J6,"") -> 0.42369117 | J6: =IFERROR('Raw Data'!O6/'Raw Data'!F6,"") -> 24.437571 | K6: =IFERROR('Raw Data'!P6/'Raw Data'!F6,"") -> 231.18431 | L6: =IFERROR('Raw Data'!O6/'Raw Data'!Q6,"") -> 53.085923 | M6: =IFERROR('Raw Data'!Y6/'Raw Data'!F6*100,"") -> 0.74899919 | N6: =IFERROR('Raw Data'!F6/'Raw Data'!Q6,"") -> 2.1723077
A7: ='Raw Data'!A7 -> AECI Limited | B7: ='Raw Data'!B7 -> AFE | C7: ='Raw Data'!C7 -> Chemicals | D7: ='Raw Data'!D7 -> 2021 | E7: =IFERROR('Raw Data'!G7/'Raw Data'!F7*100,"") -> 7.8762523 | F7: =IFERROR('Raw Data'!H7/'Raw Data'!F7*100,"") -> 4.6443788 | G7: =IFERROR('Raw Data'!H7/'Raw Data'!I7*100,"") | H7: =IFERROR('Raw Data'!H7/'Raw Data'!J7*100,"") -> 10.440935 | I7: =IFERROR('Raw Data'!K7/'Raw Data'!J7,"") -> 0.23815687 | J7: =IFERROR('Raw Data'!O7/'Raw Data'!F7,"") -> 19.242851 | K7: =IFERROR('Raw Data'!P7/'Raw Data'!F7,"") -> 67.398342 | L7: =IFERROR('Raw Data'!O7/'Raw Data'!Q7,"") -> 71.313514 | M7: =IFERROR('Raw Data'!Y7/'Raw Data'!F7*100,"") -> 0.13357387 | N7: =IFERROR('Raw Data'!F7/'Raw Data'!Q7,"") -> 3.7059744
A8: ='Raw Data'!A8 -> AECI Limited | B8: ='Raw Data'!B8 -> AFE | C8: ='Raw Data'!C8 -> Chemicals | D8: ='Raw Data'!D8 -> 2022 | E8: =IFERROR('Raw Data'!G8/'Raw Data'!F8*100,"") -> 5.7527471 | F8: =IFERROR('Raw Data'!H8/'Raw Data'!F8*100,"") -> 2.6866762 | G8: =IFERROR('Raw Data'!H8/'Raw Data'!I8*100,"") | H8: =IFERROR('Raw Data'!H8/'Raw Data'!J8*100,"") -> 8.1016949 | I8: =IFERROR('Raw Data'!K8/'Raw Data'!J8,"") -> 0.44915254 | J8: =IFERROR('Raw Data'!O8/'Raw Data'!F8,"") -> 13.877441 | K8: =IFERROR('Raw Data'!P8/'Raw Data'!F8,"") -> 50.402018 | L8: =IFERROR('Raw Data'!O8/'Raw Data'!Q8,"") -> 68.889648 | M8: =IFERROR('Raw Data'!Y8/'Raw Data'!F8*100,"") -> 0.10173397 | N8: =IFERROR('Raw Data'!F8/'Raw Data'!Q8,"") -> 4.9641462
A9: ='Raw Data'!A9 -> AECI Limited | B9: ='Raw Data'!B9 -> AFE | C9: ='Raw Data'!C9 -> Chemicals | D9: ='Raw Data'!D9 -> 2023 | E9: =IFERROR('Raw Data'!G9/'Raw Data'!F9*100,"") -> 6.856 | F9: =IFERROR('Raw Data'!H9/'Raw Data'!F9*100,"") -> 3.1466667 | G9: =IFERROR('Raw Data'!H9/'Raw Data'!I9*100,"") | H9: =IFERROR('Raw Data'!H9/'Raw Data'!J9*100,"") -> 9.516129 | I9: =IFERROR('Raw Data'!K9/'Raw Data'!J9,"") -> 0.34677419 | J9: =IFERROR('Raw Data'!O9/'Raw Data'!F9,"") -> 11.730347 | K9: =IFERROR('Raw Data'!P9/'Raw Data'!F9,"") -> 44.769733 | L9: =IFERROR('Raw Data'!O9/'Raw Data'!Q9,"") -> 61.189039 | M9: =IFERROR('Raw Data'!Y9/'Raw Data'!F9*100,"") -> 0.10666667 | N9: =IFERROR('Raw Data'!F9/'Raw Data'!Q9,"") -> 5.2163027
A10: ='Raw Data'!A10 -> AECI Limited | B10: ='Raw Data'!B10 -> AFE | C10: ='Raw Data'!C10 -> Chemicals | D10: ='Raw Data'!D10 -> 2024 | E10: =IFERROR('Raw Data'!G10/'Raw Data'!F10*100,"") -> 0 | F10: =IFERROR('Raw Data'!H10/'Raw Data'!F10*100,"") -> -0.75897375 | G10: =IFERROR('Raw Data'!H10/'Raw Data'!I10*100,"") | H10: =IFERROR('Raw Data'!H10/'Raw Data'!J10*100,"") -> -2.107438 | I10: =IFERROR('Raw Data'!K10/'Raw Data'!J10,"") -> 0.30892562 | J10: =IFERROR('Raw Data'!O10/'Raw Data'!F10,"") -> 12.39172 | K10: =IFERROR('Raw Data'!P10/'Raw Data'!F10,"") -> 48.75439 | L10: =IFERROR('Raw Data'!O10/'Raw Data'!Q10,"") -> 60.008216 | M10: =IFERROR('Raw Data'!Y10/'Raw Data'!F10*100,"") -> 0.084826478 | N10: =IFERROR('Raw Data'!F10/'Raw Data'!Q10,"") -> 4.8426059
A11: ='Raw Data'!A11 -> AECI Limited | B11: ='Raw Data'!B11 -> AFE | C11: ='Raw Data'!C11 -> Chemicals | D11: ='Raw Data'!D11 -> 2025 | E11: =IFERROR('Raw Data'!G11/'Raw Data'!F11*100,"") -> 4.7540627 | F11: =IFERROR('Raw Data'!H11/'Raw Data'!F11*100,"") -> 0 | G11: =IFERROR('Raw Data'!H11/'Raw Data'!I11*100,"") | H11: =IFERROR('Raw Data'!H11/'Raw Data'!J11*100,"") -> 0 | I11: =IFERROR('Raw Data'!K11/'Raw Data'!J11,"") -> 0.040086207 | J11: =IFERROR('Raw Data'!O11/'Raw Data'!F11,"") -> 11.356928 | K11: =IFERROR('Raw Data'!P11/'Raw Data'!F11,"") -> 48.27471 | L11: =IFERROR('Raw Data'!O11/'Raw Data'!Q11,"") -> 66.953655 | M11: =IFERROR('Raw Data'!Y11/'Raw Data'!F11*100,"") -> 0.10253861 | N11: =IFERROR('Raw Data'!F11/'Raw Data'!Q11,"") -> 5.8954021
A12: ='Raw Data'!A12 -> ArcelorMittal South Africa | B12: ='Raw Data'!B12 -> AMS | C12: ='Raw Data'!C12 -> Steel & Metals | D12: ='Raw Data'!D12 -> 2021 | E12: =IFERROR('Raw Data'!G12/'Raw Data'!F12*100,"") -> 20.086632 | F12: =IFERROR('Raw Data'!H12/'Raw Data'!F12*100,"") -> 16.684295 | G12: =IFERROR('Raw Data'!H12/'Raw Data'!I12*100,"") -> 22.771801 | H12: =IFERROR('Raw Data'!H12/'Raw Data'!J12*100,"") -> 73.180161 | I12: =IFERROR('Raw Data'!K12/'Raw Data'!J12,"") -> 0.65282227 | J12: =IFERROR('Raw Data'!O12/'Raw Data'!F12,"") -> 211.79611 | K12: =IFERROR('Raw Data'!P12/'Raw Data'!F12,"") -> 302.72761 | L12: =IFERROR('Raw Data'!O12/'Raw Data'!Q12,"") -> 1179.0271 | M12: =IFERROR('Raw Data'!Y12/'Raw Data'!F12*100,"") -> 0.039034955 | N12: =IFERROR('Raw Data'!F12/'Raw Data'!Q12,"") -> 5.5668022
A13: ='Raw Data'!A13 -> ArcelorMittal South Africa | B13: ='Raw Data'!B13 -> AMS | C13: ='Raw Data'!C13 -> Steel & Metals | D13: ='Raw Data'!D13 -> 2022 | E13: =IFERROR('Raw Data'!G13/'Raw Data'!F13*100,"") -> 8.5820804 | F13: =IFERROR('Raw Data'!H13/'Raw Data'!F13*100,"") -> 6.4604744 | G13: =IFERROR('Raw Data'!H13/'Raw Data'!I13*100,"") -> 8.7797073 | H13: =IFERROR('Raw Data'!H13/'Raw Data'!J13*100,"") -> 22.561028 | I13: =IFERROR('Raw Data'!K13/'Raw Data'!J13,"") -> 0.53104925 | J13: =IFERROR('Raw Data'!O13/'Raw Data'!F13,"") -> 204.80243 | K13: =IFERROR('Raw Data'!P13/'Raw Data'!F13,"") -> 280.0598 | L13: =IFERROR('Raw Data'!O13/'Raw Data'!Q13,"") -> 1294.5736 | M13: =IFERROR('Raw Data'!Y13/'Raw Data'!F13*100,"") -> 0.040960487 | N13: =IFERROR('Raw Data'!F13/'Raw Data'!Q13,"") -> 6.3210853
... A26: ='Raw Data'!A26 -> Sasol Limited | B26: ='Raw Data'!B26 -> SOL | C26: ='Raw Data'!C26 -> Energy & Chemicals | D26: ='Raw Data'!D26 -> 2025 | E26: =IFERROR('Raw Data'!G26/'Raw Data'!F26*100,"") -> 7.5549186 | F26: =IFERROR('Raw Data'!H26/'Raw Data'!F26*100,"") -> 2.7166233 | G26: =IFERROR('Raw Data'!H26/'Raw Data'!I26*100,"") -> 1.8820486 | H26: =IFERROR('Raw Data'!H26/'Raw Data'!J26*100,"") -> 4.2934821 | I26: =IFERROR('Raw Data'!K26/'Raw Data'!J26,"") -> 0.65541111 | J26: =IFERROR('Raw Data'!O26/'Raw Data'!F26,"") -> 235.76452 | K26: =IFERROR('Raw Data'!P26/'Raw Data'!F26,"") -> 512.88852 | L26: =IFERROR('Raw Data'!O26/'Raw Data'!Q26,"") -> 2166.5253 | M26: =IFERROR('Raw Data'!Y26/'Raw Data'!F26*100,"") -> 0.26628288 | N26: =IFERROR('Raw Data'!F26/'Raw Data'!Q26,"") -> 9.1893607

Sheet ESG Index
A1: Composite ESG-Financial Decision Index (0-100, higher = better)
A2: Methodology: each of six sub-indicators is min-max normalised to 0-100 across all 25 company-year observations (worst observed value = 0, best = 100), then combined using the equal weights shown in row 4 below, following common ESG-index-construction practice (e.g. Escrig-Olmedo et al., 2019; Berg, Koelbel & Rigobon, 2022, on weighting choices in ESG scoring methodologies). Weights are fully transparent and adjustable in row 4 -- changing a weight recalculates every score live. GHG intensity, water intensity, safety incidents and B-BBEE level are 'lower is better' and are inverted (100 minus the normalised score) before weighting.
A4: Weight | B4: 0.2 | C4: 0.15 | D4: 0.2 | E4: 0.15 | F4: 0.15 | G4: 0.15 | H4: Sum of weights: | I4: =SUM(B4:G4) -> 1
A5: Sub-indicator | B5: GHG Intensity (inverted) | C5: Water Intensity (inverted) | D5: Safety Value (inverted) | E5: B-BBEE Level (inverted) | F5: Board Women % | G5: CSI Intensity (% revenue) | H5: Sector | I5: ESG Index Score | J5: Composite Rank (year) | K5: Company | L5: FY
B6: =IFERROR(IF(Ratios!J2="","",100-((Ratios!J2-MIN(Ratios!$J$2:$J$26))/(MAX(Ratios!$J$2:$J$26)-MIN(Ratios!$J$2:$J$26))*100)),"") -> 90.687542 | C6: =IFERROR(IF(Ratios!K2="","",100-((Ratios!K2-MIN(Ratios!$K$2:$K$26))/(MAX(Ratios!$K$2:$K$26)-MIN(Ratios!$K$2:$K$26))*100)),"") -> 85.057586 | D6: =IFERROR(IF('Raw Data'!S2="","",100-(('Raw Data'!S2-MIN('Raw Data'!$S$2:$S$26))/(MAX('Raw Data'!$S$2:$S$26)-MIN('Raw Data'!$S$2:$S$26))*100)),"") -> 47.272727 | E6: =IFERROR(IF('Raw Data'!U2="","",100-(('Raw Data'!U2-MIN('Raw Data'!$U$2:$U$26))/(MAX('Raw Data'!$U$2:$U$26)-MIN('Raw Data'!$U$2:$U$26))*100)),"") -> 83.333333 | F6: =IFERROR(IF('Raw Data'!V2="","",(('Raw Data'!V2-MIN('Raw Data'!$V$2:$V$26))/(MAX('Raw Data'!$V$2:$V$26)-MIN('Raw Data'!$V$2:$V$26))*100)),"") -> 0 | G6: =IFERROR(IF(Ratios!M2="","",(Ratios!M2-MIN(Ratios!$M$2:$M$26))/(MAX(Ratios!$M$2:$M$26)-MIN(Ratios!$M$2:$M$26))*100),"") -> 55.397165 | H6: ='Raw Data'!C2 -> Construction Materials & Mining | I6: =IFERROR(SUMPRODUCT(B6:G6,$B$4:$G$4)/SUMPRODUCT(--(B6:G6<>""),$B$4:$G$4),"") -> 61.160266 | J6: =IFERROR(SUMPRODUCT((($L$6:$L$30=$L$6)*($I$6:$I$30>I6)))+1,"") -> 3 | K6: ='Raw Data'!A2 -> Afrimat Limited | L6: ='Raw Data'!D2 -> 2021
B7: =IFERROR(IF(Ratios!J3="","",100-((Ratios!J3-MIN(Ratios!$J$2:$J$26))/(MAX(Ratios!$J$2:$J$26)-MIN(Ratios!$J$2:$J$26))*100)),"") -> 90.737781 | C7: =IFERROR(IF(Ratios!K3="","",100-((Ratios!K3-MIN(Ratios!$K$2:$K$26))/(MAX(Ratios!$K$2:$K$26)-MIN(Ratios!$K$2:$K$26))*100)),"") -> 79.918728 | D7: =IFERROR(IF('Raw Data'!S3="","",100-(('Raw Data'!S3-MIN('Raw Data'!$S$2:$S$26))/(MAX('Raw Data'!$S$2:$S$26)-MIN('Raw Data'!$S$2:$S$26))*100)),"") -> 50 | E7: =IFERROR(IF('Raw Data'!U3="","",100-(('Raw Data'!U3-MIN('Raw Data'!$U$2:$U$26))/(MAX('Raw Data'!$U$2:$U$26)-MIN('Raw Data'!$U$2:$U$26))*100)),"") -> 83.333333 | F7: =IFERROR(IF('Raw Data'!V3="","",(('Raw Data'!V3-MIN('Raw Data'!$V$2:$V$26))/(MAX('Raw Data'!$V$2:$V$26)-MIN('Raw Data'!$V$2:$V$26))*100)),"") -> 16.666667 | G7: =IFERROR(IF(Ratios!M3="","",(Ratios!M3-MIN(Ratios!$M$2:$M$26))/(MAX(Ratios!$M$2:$M$26)-MIN(Ratios!$M$2:$M$26))*100),"") -> 66.01399 | H7: ='Raw Data'!C3 -> Construction Materials & Mining | I7: =IFERROR(SUMPRODUCT(B7:G7,$B$4:$G$4)/SUMPRODUCT(--(B7:G7<>""),$B$4:$G$4),"") -> 65.037464 | J7: =IFERROR(SUMPRODUCT((($L$6:$L$30=$L$7)*($I$6:$I$30>I7)))+1,"") -> 3 | K7: ='Raw Data'!A3 -> Afrimat Limited | L7: ='Raw Data'!D3 -> 2022
B8: =IFERROR(IF(Ratios!J4="","",100-((Ratios!J4-MIN(Ratios!$J$2:$J$26))/(MAX(Ratios!$J$2:$J$26)-MIN(Ratios!$J$2:$J$26))*100)),"") -> 91.706108 | C8: =IFERROR(IF(Ratios!K4="","",100-((Ratios!K4-MIN(Ratios!$K$2:$K$26))/(MAX(Ratios!$K$2:$K$26)-MIN(Ratios!$K$2:$K$26))*100)),"") -> 62.853314 | D8: =IFERROR(IF('Raw Data'!S4="","",100-(('Raw Data'!S4-MIN('Raw Data'!$S$2:$S$26))/(MAX('Raw Data'!$S$2:$S$26)-MIN('Raw Data'!$S$2:$S$26))*100)),"") -> 71.818182 | E8: =IFERROR(IF('Raw Data'!U4="","",100-(('Raw Data'!U4-MIN('Raw Data'!$U$2:$U$26))/(MAX('Raw Data'!$U$2:$U$26)-MIN('Raw Data'!$U$2:$U$26))*100)),"") -> 100 | F8: =IFERROR(IF('Raw Data'!V4="","",(('Raw Data'!V4-MIN('Raw Data'!$V$2:$V$26))/(MAX('Raw Data'!$V$2:$V$26)-MIN('Raw Data'!$V$2:$V$26))*100)),"") -> 21.428571 | G8: =IFERROR(IF(Ratios!M4="","",(Ratios!M4-MIN(Ratios!$M$2:$M$26))/(MAX(Ratios!$M$2:$M$26)-MIN(Ratios!$M$2:$M$26))*100),"") -> 84.36774 | H8: ='Raw Data'!C4 -> Construction Materials & Mining | I8: =IFERROR(SUMPRODUCT(B8:G8,$B$4:$G$4)/SUMPRODUCT(--(B8:G8<>""),$B$4:$G$4),"") -> 73.002302 | J8: =IFERROR(SUMPRODUCT((($L$6:$L$30=$L$8)*($I$6:$I$30>I8)))+1,"") -> 3 | K8: ='Raw Data'!A4 -> Afrimat Limited | L8: ='Raw Data'!D4 -> 2023
B9: =IFERROR(IF(Ratios!J5="","",100-((Ratios!J5-MIN(Ratios!$J$2:$J$26))/(MAX(Ratios!$J$2:$J$26)-MIN(Ratios!$J$2:$J$26))*100)),"") -> 92.952781 | C9: =IFERROR(IF(Ratios!K5="","",100-((Ratios!K5-MIN(Ratios!$K$2:$K$26))/(MAX(Ratios!$K$2:$K$26)-MIN(Ratios!$K$2:$K$26))*100)),"") -> 66.179148 | D9: =IFERROR(IF('Raw Data'!S5="","",100-(('Raw Data'!S5-MIN('Raw Data'!$S$2:$S$26))/(MAX('Raw Data'!$S$2:$S$26)-MIN('Raw Data'!$S$2:$S$26))*100)),"") -> 76.363636 | E9: =IFERROR(IF('Raw Data'!U5="","",100-(('Raw Data'!U5-MIN('Raw Data'!$U$2:$U$26))/(MAX('Raw Data'!$U$2:$U$26)-MIN('Raw Data'!$U$2:$U$26))*100)),"") -> 100 | F9: =IFERROR(IF('Raw Data'!V5="","",(('Raw Data'!V5-MIN('Raw Data'!$V$2:$V$26))/(MAX('Raw Data'!$V$2:$V$26)-MIN('Raw Data'!$V$2:$V$26))*100)),"") -> 21.428571 | G9: =IFERROR(IF(Ratios!M5="","",(Ratios!M5-MIN(Ratios!$M$2:$M$26))/(MAX(Ratios!$M$2:$M$26)-MIN(Ratios!$M$2:$M$26))*100),"") -> 100 | H9: ='Raw Data'!C5 -> Construction Materials & Mining | I9: =IFERROR(SUMPRODUCT(B9:G9,$B$4:$G$4)/SUMPRODUCT(--(B9:G9<>""),$B$4:$G$4),"") -> 77.004441 | J9: =IFERROR(SUMPRODUCT((($L$6:$L$30=$L$9)*($I$6:$I$30>I9)))+1,"") -> 2 | K9: ='Raw Data'!A5 -> Afrimat Limited | L9: ='Raw Data'!D5 -> 2024
B10: =IFERROR(IF(Ratios!J6="","",100-((Ratios!J6-MIN(Ratios!$J$2:$J$26))/(MAX(Ratios!$J$2:$J$26)-MIN(Ratios!$J$2:$J$26))*100)),"") -> 94.394358 | C10: =IFERROR(IF(Ratios!K6="","",100-((Ratios!K6-MIN(Ratios!$K$2:$K$26))/(MAX(Ratios!$K$2:$K$26)-MIN(Ratios!$K$2:$K$26))*100)),"") -> 70.82489 | D10: =IFERROR(IF('Raw Data'!S6="","",100-(('Raw Data'!S6-MIN('Raw Data'!$S$2:$S$26))/(MAX('Raw Data'!$S$2:$S$26)-MIN('Raw Data'!$S$2:$S$26))*100)),"") -> 78.181818 | E10: =IFERROR(IF('Raw Data'!U6="","",100-(('Raw Data'!U6-MIN('Raw Data'!$U$2:$U$26))/(MAX('Raw Data'!$U$2:$U$26)-MIN('Raw Data'!$U$2:$U$26))*100)),"") -> 100 | F10: =IFERROR(IF('Raw Data'!V6="","",(('Raw Data'!V6-MIN('Raw Data'!$V$2:$V$26))/(MAX('Raw Data'!$V$2:$V$26)-MIN('Raw Data'!$V$2:$V$26))*100)),"") -> 21.428571 | G10: =IFERROR(IF(Ratios!M6="","",(Ratios!M6-MIN(Ratios!$M$2:$M$26))/(MAX(Ratios!$M$2:$M$26)-MIN(Ratios!$M$2:$M$26))*100),"") -> 60.637239 | H10: ='Raw Data'!C6 -> Construction Materials & Mining | I10: =IFERROR(SUMPRODUCT(B10:G10,$B$4:$G$4)/SUMPRODUCT(--(B10:G10<>""),$B$4:$G$4),"") -> 72.44884 | J10: =IFERROR(SUMPRODUCT((($L$6:$L$30=$L$10)*($I$6:$I$30>I10)))+1,"") -> 3 | K10: ='Raw Data'!A6 -> Afrimat Limited | L10: ='Raw Data'!D6 -> 2025
B11: =IFERROR(IF(Ratios!J7="","",100-((Ratios!J7-MIN(Ratios!$J$2:$J$26))/(MAX(Ratios!$J$2:$J$26)-MIN(Ratios!$J$2:$J$26))*100)),"") -> 95.986936 | C11: =IFERROR(IF(Ratios!K7="","",100-((Ratios!K7-MIN(Ratios!$K$2:$K$26))/(MAX(Ratios!$K$2:$K$26)-MIN(Ratios!$K$2:$K$26))*100)),"") -> 96.458474 | D11: =IFERROR(IF('Raw Data'!S7="","",100-(('Raw Data'!S7-MIN('Raw Data'!$S$2:$S$26))/(MAX('Raw Data'!$S$2:$S$26)-MIN('Raw Data'!$S$2:$S$26))*100)),"") -> 81.818182 | E11: =IFERROR(IF('Raw Data'!U7="","",100-(('Raw Data'!U7-MIN('Raw Data'!$U$2:$U$26))/(MAX('Raw Data'!$U$2:$U$26)-MIN('Raw Data'!$U$2:$U$26))*100)),"") -> 83.333333 | F11: =IFERROR(IF('Raw Data'!V7="","",(('Raw Data'!V7-MIN('Raw Data'!$V$2:$V$26))/(MAX('Raw Data'!$V$2:$V$26)-MIN('Raw Data'!$V$2:$V$26))*100)),"") -> 66.666667 | G11: =IFERROR(IF(Ratios!M7="","",(Ratios!M7-MIN(Ratios!$M$2:$M$26))/(MAX(Ratios!$M$2:$M$26)-MIN(Ratios!$M$2:$M$26))*100),"") -> 8.0744612 | H11: ='Raw Data'!C7 -> Chemicals | I11: =IFERROR(SUMPRODUCT(B11:G11,$B$4:$G$4)/SUMPRODUCT(--(B11:G11<>""),$B$4:$G$4),"") -> 73.740964 | J11: =IFERROR(SUMPRODUCT((($L$6:$L$30=$L$11)*($I$6:$I$30>I11)))+1,"") -> 1 | K11: ='Raw Data'!A7 -> AECI Limited | L11: ='Raw Data'!D7 -> 2021
B12: =IFERROR(IF(Ratios!J8="","",100-((Ratios!J8-MIN(Ratios!$J$2:$J$26))/(MAX(Ratios!$J$2:$J$26)-MIN(Ratios!$J$2:$J$26))*100)),"") -> 97.631842 | C12: =IFERROR(IF(Ratios!K8="","",100-((Ratios!K8-MIN(Ratios!$K$2:$K$26))/(MAX(Ratios!$K$2:$K$26)-MIN(Ratios!$K$2:$K$26))*100)),"") -> 99.11851 | D12: =IFERROR(IF('Raw Data'!S8="","",100-(('Raw Data'!S8-MIN('Raw Data'!$S$2:$S$26))/(MAX('Raw Data'!$S$2:$S$26)-MIN('Raw Data'!$S$2:$S$26))*100)),"") -> 89.090909 | E12: =IFERROR(IF('Raw Data'!U8="","",100-(('Raw Data'!U8-MIN('Raw Data'!$U$2:$U$26))/(MAX('Raw Data'!$U$2:$U$26)-MIN('Raw Data'!$U$2:$U$26))*100)),"") -> 83.333333 | F12: =IFERROR(IF('Raw Data'!V8="","",(('Raw Data'!V8-MIN('Raw Data'!$V$2:$V$26))/(MAX('Raw Data'!$V$2:$V$26)-MIN('Raw Data'!$V$2:$V$26))*100)),"") -> 76.190476 | G12: =IFERROR(IF(Ratios!M8="","",(Ratios!M8-MIN(Ratios!$M$2:$M$26))/(MAX(Ratios!$M$2:$M$26)-MIN(Ratios!$M$2:$M$26))*100),"") -> 5.355052 | H12: ='Raw Data'!C8 -> Chemicals | I12: =IFERROR(SUMPRODUCT(B12:G12,$B$4:$G$4)/SUMPRODUCT(--(B12:G12<>""),$B$4:$G$4),"") -> 76.944156 | J12: =IFERROR(SUMPRODUCT((($L$6:$L$30=$L$12)*($I$6:$I$30>I12)))+1,"") -> 1 | K12: ='Raw Data'!A8 -> AECI Limited | L12: ='Raw Data'!D8 -> 2022
B13: =IFERROR(IF(Ratios!J9="","",100-((Ratios!J9-MIN(Ratios!$J$2:$J$26))/(MAX(Ratios!$J$2:$J$26)-MIN(Ratios!$J$2:$J$26))*100)),"") -> 98.29009 | C13: =IFERROR(IF(Ratios!K9="","",100-((Ratios!K9-MIN(Ratios!$K$2:$K$26))/(MAX(Ratios!$K$2:$K$26)-MIN(Ratios!$K$2:$K$26))*100)),"") -> 100 | D13: =IFERROR(IF('Raw Data'!S9="","",100-(('Raw Data'!S9-MIN('Raw Data'!$S$2:$S$26))/(MAX('Raw Data'!$S$2:$S$26)-MIN('Raw Data'!$S$2:$S$26))*100)),"") -> 70.909091 | E13: =IFERROR(IF('Raw Data'!U9="","",100-(('Raw Data'!U9-MIN('Raw Data'!$U$2:$U$26))/(MAX('Raw Data'!$U$2:$U$26)-MIN('Raw Data'!$U$2:$U$26))*100)),"") -> 83.333333 | F13: =IFERROR(IF('Raw Data'!V9="","",(('Raw Data'!V9-MIN('Raw Data'!$V$2:$V$26))/(MAX('Raw Data'!$V$2:$V$26)-MIN('Raw Data'!$V$2:$V$26))*100)),"") -> 100 | G13: =IFERROR(IF(Ratios!M9="","",(Ratios!M9-MIN(Ratios!$M$2:$M$26))/(MAX(Ratios!$M$2:$M$26)-MIN(Ratios!$M$2:$M$26))*100),"") -> 5.7763476 | H13: ='Raw Data'!C9 -> Chemicals | I13: =IFERROR(SUMPRODUCT(B13:G13,$B$4:$G$4)/SUMPRODUCT(--(B13:G13<>""),$B$4:$G$4),"") -> 77.206288 | J13: =IFERROR(SUMPRODUCT((($L$6:$L$30=$L$13)*($I$6:$I$30>I13)))+1,"") -> 2 | K13: ='Raw Data'!A9 -> AECI Limited | L13: ='Raw Data'!D9 -> 2023
B14: =IFERROR(IF(Ratios!J10="","",100-((Ratios!J10-MIN(Ratios!$J$2:$J$26))/(MAX(Ratios!$J$2:$J$26)-MIN(Ratios!$J$2:$J$26))*100)),"") -> 98.087329 | C14: =IFERROR(IF(Ratios!K10="","",100-((Ratios!K10-MIN(Ratios!$K$2:$K$26))/(MAX(Ratios!$K$2:$K$26)-MIN(Ratios!$K$2:$K$26))*100)),"") -> 99.376375 | D14: =IFERROR(IF('Raw Data'!S10="","",100-(('Raw Data'!S10-MIN('Raw Data'!$S$2:$S$26))/(MAX('Raw Data'!$S$2:$S$26)-MIN('Raw Data'!$S$2:$S$26))*100)),"") -> 74.545455 | E14: =IFERROR(IF('Raw Data'!U10="","",100-(('Raw Data'!U10-MIN('Raw Data'!$U$2:$U$26))/(MAX('Raw Data'!$U$2:$U$26)-MIN('Raw Data'!$U$2:$U$26))*100)),"") -> 83.333333 | F14: =IFERROR(IF('Raw Data'!V10="","",(('Raw Data'!V10-MIN('Raw Data'!$V$2:$V$26))/(MAX('Raw Data'!$V$2:$V$26)-MIN('Raw Data'!$V$2:$V$26))*100)),"") -> 85.714286 | G14: =IFERROR(IF(Ratios!M10="","",(Ratios!M10-MIN(Ratios!$M$2:$M$26))/(MAX(Ratios!$M$2:$M$26)-MIN(Ratios!$M$2:$M$26))*100),"") -> 3.9110019 | H14: ='Raw Data'!C10 -> Chemicals | I14: =IFERROR(SUMPRODUCT(B14:G14,$B$4:$G$4)/SUMPRODUCT(--(B14:G14<>""),$B$4:$G$4),"") -> 75.376806 | J14: =IFERROR(SUMPRODUCT((($L$6:$L$30=$L$14)*($I$6:$I$30>I14)))+1,"") -> 3 | K14: ='Raw Data'!A10 -> AECI Limited | L14: ='Raw Data'!D10 -> 2024
B15: =IFERROR(IF(Ratios!J11="","",100-((Ratios!J11-MIN(Ratios!$J$2:$J$26))/(MAX(Ratios!$J$2:$J$26)-MIN(Ratios!$J$2:$J$26))*100)),"") -> 98.404571 | C15: =IFERROR(IF(Ratios!K11="","",100-((Ratios!K11-MIN(Ratios!$K$2:$K$26))/(MAX(Ratios!$K$2:$K$26)-MIN(Ratios!$K$2:$K$26))*100)),"") -> 99.451448 | D15: =IFERROR(IF('Raw Data'!S11="","",100-(('Raw Data'!S11-MIN('Raw Data'!$S$2:$S$26))/(MAX('Raw Data'!$S$2:$S$26)-MIN('Raw Data'!$S$2:$S$26))*100)),"") -> 84.545455 | E15: =IFERROR(IF('Raw Data'!U11="","",100-(('Raw Data'!U11-MIN('Raw Data'!$U$2:$U$26))/(MAX('Raw Data'!$U$2:$U$26)-MIN('Raw Data'!$U$2:$U$26))*100)),"") | F15: =IFERROR(IF('Raw Data'!V11="","",(('Raw Data'!V11-MIN('Raw Data'!$V$2:$V$26))/(MAX('Raw Data'!$V$2:$V$26)-MIN('Raw Data'!$V$2:$V$26))*100)),"") -> 100 | G15: =IFERROR(IF(Ratios!M11="","",(Ratios!M11-MIN(Ratios!$M$2:$M$26))/(MAX(Ratios!$M$2:$M$26)-MIN(Ratios!$M$2:$M$26))*100),"") -> 5.4237748 | H15: ='Raw Data'!C11 -> Chemicals | I15: =IFERROR(SUMPRODUCT(B15:G15,$B$4:$G$4)/SUMPRODUCT(--(B15:G15<>""),$B$4:$G$4),"") -> 79.201516 | J15: =IFERROR(SUMPRODUCT((($L$6:$L$30=$L$15)*($I$6:$I$30>I15)))+1,"") -> 1 | K15: ='Raw Data'!A11 -> AECI Limited | L15: ='Raw Data'!D11 -> 2025
B16: =IFERROR(IF(Ratios!J12="","",100-((Ratios!J12-MIN(Ratios!$J$2:$J$26))/(MAX(Ratios!$J$2:$J$26)-MIN(Ratios!$J$2:$J$26))*100)),"") -> 36.954707 | C16: =IFERROR(IF(Ratios!K12="","",100-((Ratios!K12-MIN(Ratios!$K$2:$K$26))/(MAX(Ratios!$K$2:$K$26)-MIN(Ratios!$K$2:$K$26))*100)),"") -> 59.627892 | D16: =IFERROR(IF('Raw Data'!S12="","",100-(('Raw Data'!S12-MIN('Raw Data'!$S$2:$S$26))/(MAX('Raw Data'!$S$2:$S$26)-MIN('Raw Data'!$S$2:$S$26))*100)),"") -> 13.636364 | E16: =IFERROR(IF('Raw Data'!U12="","",100-(('Raw Data'!U12-MIN('Raw Data'!$U$2:$U$26))/(MAX('Raw Data'!$U$2:$U$26)-MIN('Raw Data'!$U$2:$U$26))*100)),"") -> 0 | F16: =IFERROR(IF('Raw Data'!V12="","",(('Raw Data'!V12-MIN('Raw Data'!$V$2:$V$26))/(MAX('Raw Data'!$V$2:$V$26)-MIN('Raw Data'!$V$2:$V$26))*100)),"") -> 88.095238 | G16: =IFERROR(IF(Ratios!M12="","",(Ratios!M12-MIN(Ratios!$M$2:$M$26))/(MAX(Ratios!$M$2:$M$26)-MIN(Ratios!$M$2:$M$26))*100),"") -> 0 | H16: ='Raw Data'!C12 -> Steel & Metals | I16: =IFERROR(SUMPRODUCT(B16:G16,$B$4:$G$4)/SUMPRODUCT(--(B16:G16<>""),$B$4:$G$4),"") -> 32.276684 | J16: =IFERROR(SUMPRODUCT((($L$6:$L$30=$L$16)*($I$6:$I$30>I16)))+1,"") -> 5 | K16: ='Raw Data'!A12 -> ArcelorMittal South Africa | L16: ='Raw Data'!D12 -> 2021
B17: =IFERROR(IF(Ratios!J13="","",100-((Ratios!J13-MIN(Ratios!$J$2:$J$26))/(MAX(Ratios!$J$2:$J$26)-MIN(Ratios!$J$2:$J$26))*100)),"") -> 39.098802 | C17: =IFERROR(IF(Ratios!K13="","",100-((Ratios!K13-MIN(Ratios!$K$2:$K$26))/(MAX(Ratios!$K$2:$K$26)-MIN(Ratios!$K$2:$K$26))*100)),"") -> 63.175555 | D17: =IFERROR(IF('Raw Data'!S13="","",100-(('Raw Data'!S13-MIN('Raw Data'!$S$2:$S$26))/(MAX('Raw Data'!$S$2:$S$26)-MIN('Raw Data'!$S$2:$S$26))*100)),"") -> 23.636364 | E17: =IFERROR(IF('Raw Data'!U13="","",100-(('Raw Data'!U13-MIN('Raw Data'!$U$2:$U$26))/(MAX('Raw Data'!$U$2:$U$26)-MIN('Raw Data'!$U$2:$U$26))*100)),"") -> 33.333333 | F17: =IFERROR(IF('Raw Data'!V13="","",(('Raw Data'!V13-MIN('Raw Data'!$V$2:$V$26))/(MAX('Raw Data'!$V$2:$V$26)-MIN('Raw Data'!$V$2:$V$26))*100)),"") -> 80.952381 | G17: =IFERROR(IF(Ratios!M13="","",(Ratios!M13-MIN(Ratios!$M$2:$M$26))/(MAX(Ratios!$M$2:$M$26)-MIN(Ratios!$M$2:$M$26))*100),"") -> 0.16445745 | H17: ='Raw Data'!C13 -> Steel & Metals | I17: =IFERROR(SUMPRODUCT(B17:G17,$B$4:$G$4)/SUMPRODUCT(--(B17:G17<>""),$B$4:$G$4),"") -> 39.190892 | J17: =IFERROR(SUMPRODUCT((($L$6:$L$30=$L$17)*($I$6:$I$30>I17)))+1,"") -> 5 | K17: ='Raw Data'!A13 -> ArcelorMittal South Africa | L17: ='Raw Data'!D13 -> 2022
B18: =IFERROR(IF(Ratios!J14="","",100-((Ratios!J14-MIN(Ratios!$J$2:$J$26))/(MAX(Ratios!$J$2:$J$26)-MIN(Ratios!$J$2:$J$26))*100)),"") -> 31.789917 | C18: =IFERROR(IF(Ratios!K14="","",100-((Ratios!K14-MIN(Ratios!$K$2:$K$26))/(MAX(Ratios!$K$2:$K$26)-MIN(Ratios!$K$2:$K$26))*100)),"") -> 66.177385 | D18: =IFERROR(IF('Raw Data'!S14="","",100-(('Raw Data'!S14-MIN('Raw Data'!$S$2:$S$26))/(MAX('Raw Data'!$S$2:$S$26)-MIN('Raw Data'!$S$2:$S$26))*100)),"") -> 32.727273 | E18: =IFERROR(IF('Raw Data'!U14="","",100-(('Raw Data'!U14-MIN('Raw Data'!$U$2:$U$26))/(MAX('Raw Data'!$U$2:$U$26)-MIN('Raw Data'!$U$2:$U$26))*100)),"") -> 33.333333 | F18: =IFERROR(IF('Raw Data'!V14="","",(('Raw Data'!V14-MIN('Raw Data'!$V$2:$V$26))/(MAX('Raw Data'!$V$2:$V$26)-MIN('Raw Data'!$V$2:$V$26))*100)),"") -> 52.380952 | G18: =IFERROR(IF(Ratios!M14="","",(Ratios!M14-MIN(Ratios!$M$2:$M$26))/(MAX(Ratios!$M$2:$M$26)-MIN(Ratios!$M$2:$M$26))*100),"") -> 0.050669672 | H18: ='Raw Data'!C14 -> Steel & Metals | I18: =IFERROR(SUMPRODUCT(B18:G18,$B$4:$G$4)/SUMPRODUCT(--(B18:G18<>""),$B$4:$G$4),"") -> 35.694789 | J18: =IFERROR(SUMPRODUCT((($L$6:$L$30=$L$18)*($I$6:$I$30>I18)))+1,"") -> 5 | K18: ='Raw Data'!A14 -> ArcelorMittal South Africa | L18: ='Raw Data'!D14 -> 2023
B19: =IFERROR(IF(Ratios!J15="","",100-((Ratios!J15-MIN(Ratios!$J$2:$J$26))/(MAX(Ratios!$J$2:$J$26)-MIN(Ratios!$J$2:$J$26))*100)),"") -> 31.588932 | C19: =IFERROR(IF(Ratios!K15="","",100-((Ratios!K15-MIN(Ratios!$K$2:$K$26))/(MAX(Ratios!$K$2:$K$26)-MIN(Ratios!$K$2:$K$26))*100)),"") -> 59.91424 | D19: =IFERROR(IF('Raw Data'!S15="","",100-(('Raw Data'!S15-MIN('Raw Data'!$S$2:$S$26))/(MAX('Raw Data'!$S$2:$S$26)-MIN('Raw Data'!$S$2:$S$26))*100)),"") -> 0 | E19: =IFERROR(IF('Raw Data'!U15="","",100-(('Raw Data'!U15-MIN('Raw Data'!$U$2:$U$26))/(MAX('Raw Data'!$U$2:$U$26)-MIN('Raw Data'!$U$2:$U$26))*100)),"") -> 16.666667 | F19: =IFERROR(IF('Raw Data'!V15="","",(('Raw Data'!V15-MIN('Raw Data'!$V$2:$V$26))/(MAX('Raw Data'!$V$2:$V$26)-MIN('Raw Data'!$V$2:$V$26))*100)),"") -> 50 | G19: =IFERROR(IF(Ratios!M15="","",(Ratios!M15-MIN(Ratios!$M$2:$M$26))/(MAX(Ratios!$M$2:$M$26)-MIN(Ratios!$M$2:$M$26))*100),"") -> 0.27308634 | H19: ='Raw Data'!C15 -> Steel & Metals | I19: =IFERROR(SUMPRODUCT(B19:G19,$B$4:$G$4)/SUMPRODUCT(--(B19:G19<>""),$B$4:$G$4),"") -> 25.345885 | J19: =IFERROR(SUMPRODUCT((($L$6:$L$30=$L$19)*($I$6:$I$30>I19)))+1,"") -> 5 | K19: ='Raw Data'!A15 -> ArcelorMittal South Africa | L19: ='Raw Data'!D15 -> 2024
B20: =IFERROR(IF(Ratios!J16="","",100-((Ratios!J16-MIN(Ratios!$J$2:$J$26))/(MAX(Ratios!$J$2:$J$26)-MIN(Ratios!$J$2:$J$26))*100)),"") -> 30.58515 | C20: =IFERROR(IF(Ratios!K16="","",100-((Ratios!K16-MIN(Ratios!$K$2:$K$26))/(MAX(Ratios!$K$2:$K$26)-MIN(Ratios!$K$2:$K$26))*100)),"") -> 45.829365 | D20: =IFERROR(IF('Raw Data'!S16="","",100-(('Raw Data'!S16-MIN('Raw Data'!$S$2:$S$26))/(MAX('Raw Data'!$S$2:$S$26)-MIN('Raw Data'!$S$2:$S$26))*100)),"") -> 46.363636 | E20: =IFERROR(IF('Raw Data'!U16="","",100-(('Raw Data'!U16-MIN('Raw Data'!$U$2:$U$26))/(MAX('Raw Data'!$U$2:$U$26)-MIN('Raw Data'!$U$2:$U$26))*100)),"") -> 66.666667 | F20: =IFERROR(IF('Raw Data'!V16="","",(('Raw Data'!V16-MIN('Raw Data'!$V$2:$V$26))/(MAX('Raw Data'!$V$2:$V$26)-MIN('Raw Data'!$V$2:$V$26))*100)),"") -> 40.47619 | G20: =IFERROR(IF(Ratios!M16="","",(Ratios!M16-MIN(Ratios!$M$2:$M$26))/(MAX(Ratios!$M$2:$M$26)-MIN(Ratios!$M$2:$M$26))*100),"") -> 0.97737687 | H20: ='Raw Data'!C16 -> Steel & Metals | I20: =IFERROR(SUMPRODUCT(B20:G20,$B$4:$G$4)/SUMPRODUCT(--(B20:G20<>""),$B$4:$G$4),"") -> 38.482197 | J20: =IFERROR(SUMPRODUCT((($L$6:$L$30=$L$20)*($I$6:$I$30>I20)))+1,"") -> 5 | K20: ='Raw Data'!A16 -> ArcelorMittal South Africa | L20: ='Raw Data'!D16 -> 2025
B21: =IFERROR(IF(Ratios!J17="","",100-((Ratios!J17-MIN(Ratios!$J$2:$J$26))/(MAX(Ratios!$J$2:$J$26)-MIN(Ratios!$J$2:$J$26))*100)),"") -> 97.379889 | C21: =IFERROR(IF(Ratios!K17="","",100-((Ratios!K17-MIN(Ratios!$K$2:$K$26))/(MAX(Ratios!$K$2:$K$26)-MIN(Ratios!$K$2:$K$26))*100)),"") -> 89.605407 | D21: =IFERROR(IF('Raw Data'!S17="","",100-(('Raw Data'!S17-MIN('Raw Data'!$S$2:$S$26))/(MAX('Raw Data'!$S$2:$S$26)-MIN('Raw Data'!$S$2:$S$26))*100)),"") -> 70.909091 | E21: =IFERROR(IF('Raw Data'!U17="","",100-(('Raw Data'!U17-MIN('Raw Data'!$U$2:$U$26))/(MAX('Raw Data'!$U$2:$U$26)-MIN('Raw Data'!$U$2:$U$26))*100)),"") -> 100 | F21: =IFERROR(IF('Raw Data'!V17="","",(('Raw Data'!V17-MIN('Raw Data'!$V$2:$V$26))/(MAX('Raw Data'!$V$2:$V$26)-MIN('Raw Data'!$V$2:$V$26))*100)),"") -> 23.809524 | G21: =IFERROR(IF(Ratios!M17="","",(Ratios!M17-MIN(Ratios!$M$2:$M$26))/(MAX(Ratios!$M$2:$M$26)-MIN(Ratios!$M$2:$M$26))*100),"") -> 8.3323723 | H21: ='Raw Data'!C17 -> Chemicals & Agriculture | I21: =IFERROR(SUMPRODUCT(B21:G21,$B$4:$G$4)/SUMPRODUCT(--(B21:G21<>""),$B$4:$G$4),"") -> 66.919892 | J21: =IFERROR(SUMPRODUCT((($L$6:$L$30=$L$21)*($I$6:$I$30>I21)))+1,"") -> 2 | K21: ='Raw Data'!A17 -> Omnia Holdings Limited | L21: ='Raw Data'!D17 -> 2021
B22: =IFERROR(IF(Ratios!J18="","",100-((Ratios!J18-MIN(Ratios!$J$2:$J$26))/(MAX(Ratios!$J$2:$J$26)-MIN(Ratios!$J$2:$J$26))*100)),"") -> 97.068125 | C22: =IFERROR(IF(Ratios!K18="","",100-((Ratios!K18-MIN(Ratios!$K$2:$K$26))/(MAX(Ratios!$K$2:$K$26)-MIN(Ratios!$K$2:$K$26))*100)),"") -> 93.420027 | D22: =IFERROR(IF('Raw Data'!S18="","",100-(('Raw Data'!S18-MIN('Raw Data'!$S$2:$S$26))/(MAX('Raw Data'!$S$2:$S$26)-MIN('Raw Data'!$S$2:$S$26))*100)),"") -> 83.636364 | E22: =IFERROR(IF('Raw Data'!U18="","",100-(('Raw Data'!U18-MIN('Raw Data'!$U$2:$U$26))/(MAX('Raw Data'!$U$2:$U$26)-MIN('Raw Data'!$U$2:$U$26))*100)),"") -> 100 | F22: =IFERROR(IF('Raw Data'!V18="","",(('Raw Data'!V18-MIN('Raw Data'!$V$2:$V$26))/(MAX('Raw Data'!$V$2:$V$26)-MIN('Raw Data'!$V$2:$V$26))*100)),"") -> 23.809524 | G22: =IFERROR(IF(Ratios!M18="","",(Ratios!M18-MIN(Ratios!$M$2:$M$26))/(MAX(Ratios!$M$2:$M$26)-MIN(Ratios!$M$2:$M$26))*100),"") -> 8.100665 | H22: ='Raw Data'!C18 -> Chemicals & Agriculture | I22: =IFERROR(SUMPRODUCT(B22:G22,$B$4:$G$4)/SUMPRODUCT(--(B22:G22<>""),$B$4:$G$4),"") -> 69.94043 | J22: =IFERROR(SUMPRODUCT((($L$6:$L$30=$L$22)*($I$6:$I$30>I22)))+1,"") -> 2 | K22: ='Raw Data'!A18 -> Omnia Holdings Limited | L22: ='Raw Data'!D18 -> 2022
B23: =IFERROR(IF(Ratios!J19="","",100-((Ratios!J19-MIN(Ratios!$J$2:$J$26))/(MAX(Ratios!$J$2:$J$26)-MIN(Ratios!$J$2:$J$26))*100)),"") -> 99.721864 | C23: =IFERROR(IF(Ratios!K19="","",100-((Ratios!K19-MIN(Ratios!$K$2:$K$26))/(MAX(Ratios!$K$2:$K$26)-MIN(Ratios!$K$2:$K$26))*100)),"") -> 97.123496 | D23: =IFERROR(IF('Raw Data'!S19="","",100-(('Raw Data'!S19-MIN('Raw Data'!$S$2:$S$26))/(MAX('Raw Data'!$S$2:$S$26)-MIN('Raw Data'!$S$2:$S$26))*100)),"") -> 93.636364 | E23: =IFERROR(IF('Raw Data'!U19="","",100-(('Raw Data'!U19-MIN('Raw Data'!$U$2:$U$26))/(MAX('Raw Data'!$U$2:$U$26)-MIN('Raw Data'!$U$2:$U$26))*100)),"") -> 100 | F23: =IFERROR(IF('Raw Data'!V19="","",(('Raw Data'!V19-MIN('Raw Data'!$V$2:$V$26))/(MAX('Raw Data'!$V$2:$V$26)-MIN('Raw Data'!$V$2:$V$26))*100)),"") -> 52.380952 | G23: =IFERROR(IF(Ratios!M19="","",(Ratios!M19-MIN(Ratios!$M$2:$M$26))/(MAX(Ratios!$M$2:$M$26)-MIN(Ratios!$M$2:$M$26))*100),"") -> 11.451586 | H23: ='Raw Data'!C19 -> Chemicals & Agriculture | I23: =IFERROR(SUMPRODUCT(B23:G23,$B$4:$G$4)/SUMPRODUCT(--(B23:G23<>""),$B$4:$G$4),"") -> 77.815051 | J23: =IFERROR(SUMPRODUCT((($L$6:$L$30=$L$23)*($I$6:$I$30>I23)))+1,"") -> 1 | K23: ='Raw Data'!A19 -> Omnia Holdings Limited | L23: ='Raw Data'!D19 -> 2023
B24: =IFERROR(IF(Ratios!J20="","",100-((Ratios!J20-MIN(Ratios!$J$2:$J$26))/(MAX(Ratios!$J$2:$J$26)-MIN(Ratios!$J$2:$J$26))*100)),"") -> 99.723385 | C24: =IFERROR(IF(Ratios!K20="","",100-((Ratios!K20-MIN(Ratios!$K$2:$K$26))/(MAX(Ratios!$K$2:$K$26)-MIN(Ratios!$K$2:$K$26))*100)),"") -> 95.821176 | D24: =IFERROR(IF('Raw Data'!S20="","",100-(('Raw Data'!S20-MIN('Raw Data'!$S$2:$S$26))/(MAX('Raw Data'!$S$2:$S$26)-MIN('Raw Data'!$S$2:$S$26))*100)),"") -> 100 | E24: =IFERROR(IF('Raw Data'!U20="","",100-(('Raw Data'!U20-MIN('Raw Data'!$U$2:$U$26))/(MAX('Raw Data'!$U$2:$U$26)-MIN('Raw Data'!$U$2:$U$26))*100)),"") -> 100 | F24: =IFERROR(IF('Raw Data'!V20="","",(('Raw Data'!V20-MIN('Raw Data'!$V$2:$V$26))/(MAX('Raw Data'!$V$2:$V$26)-MIN('Raw Data'!$V$2:$V$26))*100)),"") -> 52.380952 | G24: =IFERROR(IF(Ratios!M20="","",(Ratios!M20-MIN(Ratios!$M$2:$M$26))/(MAX(Ratios!$M$2:$M$26)-MIN(Ratios!$M$2:$M$26))*100),"") -> 15.808971 | H24: ='Raw Data'!C20 -> Chemicals & Agriculture | I24: =IFERROR(SUMPRODUCT(B24:G24,$B$4:$G$4)/SUMPRODUCT(--(B24:G24<>""),$B$4:$G$4),"") -> 79.546342 | J24: =IFERROR(SUMPRODUCT((($L$6:$L$30=$L$24)*($I$6:$I$30>I24)))+1,"") -> 1 | K24: ='Raw Data'!A20 -> Omnia Holdings Limited | L24: ='Raw Data'!D20 -> 2024
B25: =IFERROR(IF(Ratios!J21="","",100-((Ratios!J21-MIN(Ratios!$J$2:$J$26))/(MAX(Ratios!$J$2:$J$26)-MIN(Ratios!$J$2:$J$26))*100)),"") -> 100 | C25: =IFERROR(IF(Ratios!K21="","",100-((Ratios!K21-MIN(Ratios!$K$2:$K$26))/(MAX(Ratios!$K$2:$K$26)-MIN(Ratios!$K$2:$K$26))*100)),"") -> 96.114811 | D25: =IFERROR(IF('Raw Data'!S21="","",100-(('Raw Data'!S21-MIN('Raw Data'!$S$2:$S$26))/(MAX('Raw Data'!$S$2:$S$26)-MIN('Raw Data'!$S$2:$S$26))*100)),"") -> 87.272727 | E25: =IFERROR(IF('Raw Data'!U21="","",100-(('Raw Data'!U21-MIN('Raw Data'!$U$2:$U$26))/(MAX('Raw Data'!$U$2:$U$26)-MIN('Raw Data'!$U$2:$U$26))*100)),"") -> 100 | F25: =IFERROR(IF('Raw Data'!V21="","",(('Raw Data'!V21-MIN('Raw Data'!$V$2:$V$26))/(MAX('Raw Data'!$V$2:$V$26)-MIN('Raw Data'!$V$2:$V$26))*100)),"") -> 52.380952 | G25: =IFERROR(IF(Ratios!M21="","",(Ratios!M21-MIN(Ratios!$M$2:$M$26))/(MAX(Ratios!$M$2:$M$26)-MIN(Ratios!$M$2:$M$26))*100),"") -> 18.937203 | H25: ='Raw Data'!C21 -> Chemicals & Agriculture | I25: =IFERROR(SUMPRODUCT(B25:G25,$B$4:$G$4)/SUMPRODUCT(--(B25:G25<>""),$B$4:$G$4),"") -> 77.56949 | J25: =IFERROR(SUMPRODUCT((($L$6:$L$30=$L$25)*($I$6:$I$30>I25)))+1,"") -> 2 | K25: ='Raw Data'!A21 -> Omnia Holdings Limited | L25: ='Raw Data'!D21 -> 2025
